Workbook

Sheet Dist expedição
A1: Onda | B1: ID da Rota | C1: Rota otimizada | D1: Rota original | E1: Doca | F1: Transportadora | G1: Placa | H1: Tipo de veículo | I1: Tipo de rota | J1: Tipo de área | K1: SPR | L1: Cluster | P1: Onda - Vaga | Q1: Vaga ( Não mexer) | R1: Rota Otimizada | S1: Rota_Original | T1: Onda
A2: Onda 3 | B2: 503162210016 | C2: VM9_AM1 | D2: AM1_52 | E2: 1 | F2: PARCEIRO SPOT SOLUCOES | G2: TEI0I29 | H2: Vuc Vamos 2025 | J2: Comercial - Distante | K2: 95 | L2: AM1 - C 3 | P2: =IFERROR(CONCATENATE(A2," - ",Q2),"") -> Onda 3 - DOCA 1 | Q2: =IFERROR(CONCATENATE(IF(OR(E2=1,E2=2),CONCAT("DOCA ",E2),E2)),"") -> DOCA 1 | R2: =C2 -> VM9_AM1 | S2: =D2 -> AM1_52 | T2: =A2:A447 -> Onda 3
A3: Onda 3 | B3: 503162211008 | C3: VN7_AM1 | D3: AM1_64 | E3: 2 | F3: PARCEIRO SPOT SOLUCOES | G3: TEI0I39 | H3: Vuc Vamos 2025 | I3: Híbrida | J3: Comercial - Distante | K3: 277 | L3: AM1 - C 2 | P3: =IFERROR(CONCATENATE(A3," - ",Q3),"") -> Onda 3 - DOCA 2 | Q3: =IFERROR(CONCATENATE(IF(OR(E3=1,E3=2),CONCAT("DOCA ",E3),E3)),"") -> DOCA 2 | R3: =C3 -> VN7_AM1 | S3: =D3 -> AM1_64 | T3: =A3:A448 -> Onda 3
A4: Onda 3 | B4: 503162697006 | C4: Q11_AM1 | D4: AM1_118 | E4: 9 | F4: PARCEIRO SPOT SOLUCOES | G4: TBK4I42 | H4: Utilitário Arval 2025 | J4: Distante | K4: 22 | L4: AM1 - C 4 | P4: =IFERROR(CONCATENATE(A4," - ",Q4),"") -> Onda 3 - 9 | Q4: =IFERROR(CONCATENATE(IF(OR(E4=1,E4=2),CONCAT("DOCA ",E4),E4)),"") -> 9 | R4: =C4 -> Q11_AM1 | S4: =D4 -> AM1_118 | T4: =A4:A449 -> Onda 3
A5: Onda 3 | B5: 503162210020 | C5: P11_AM1 | D5: AM1_56 | E5: 10 | F5: RodaCoop | G5: RUT0H49 | H5: Utilitários | J5: Comercial - Distante | K5: 90 | L5: AM1 - C 3 | P5: =IFERROR(CONCATENATE(A5," - ",Q5),"") -> Onda 3 - 10 | Q5: =IFERROR(CONCATENATE(IF(OR(E5=1,E5=2),CONCAT("DOCA ",E5),E5)),"") -> 10 | R5: =C5 -> P11_AM1 | S5: =D5 -> AM1_56 | T5: =A5:A450 -> Onda 3
A6: Onda 3 | B6: 503162211015 | C6: P1_AM1 | D6: AM1_71 | E6: 11 | F6: HELP ME SOLUCOES | G6: HJU1E10 | H6: Utilitários | J6: Comercial - Distante | K6: 138 | L6: AM1 - C 2 | P6: =IFERROR(CONCATENATE(A6," - ",Q6),"") -> Onda 3 - 11 | Q6: =IFERROR(CONCATENATE(IF(OR(E6=1,E6=2),CONCAT("DOCA ",E6),E6)),"") -> 11 | R6: =C6 -> P1_AM1 | S6: =D6 -> AM1_71 | T6: =A6:A451 -> Onda 3
A7: Onda 3 | B7: 503162209002 | C7: Q2_AM1 | D7: AM1_16 | E7: 12 | F7: Hawk Transportes | G7: SDDPYV3E07 | H7: Utilitários SDD | J7: Distante | K7: 140 | L7: AM1 - C 8 | P7: =IFERROR(CONCATENATE(A7," - ",Q7),"") -> Onda 3 - 12 | Q7: =IFERROR(CONCATENATE(IF(OR(E7=1,E7=2),CONCAT("DOCA ",E7),E7)),"") -> 12 | R7: =C7 -> Q2_AM1 | S7: =D7 -> AM1_16 | T7: =A7:A452 -> Onda 3
A8: Onda 3 | B8: 503162211010 | C8: P10_AM1 | D8: AM1_66 | E8: 13 | F8: Hawk Transportes | G8: QOV9439 | H8: Utilitários | J8: Comercial - Distante | K8: 91 | L8: AM1 - C 2 | P8: =IFERROR(CONCATENATE(A8," - ",Q8),"") -> Onda 3 - 13 | Q8: =IFERROR(CONCATENATE(IF(OR(E8=1,E8=2),CONCAT("DOCA ",E8),E8)),"") -> 13 | R8: =C8 -> P10_AM1 | S8: =D8 -> AM1_66 | T8: =A8:A453 -> Onda 3
A9: Onda 3 | B9: 503162210006 | C9: P12_AM1 | D9: AM1_42 | E9: 14 | F9: Hawk Transportes | G9: SDDRCB7E59 | H9: Utilitários SDD | J9: Comercial - Distante | K9: 75 | L9: AM1 - C 3 | P9: =IFERROR(CONCATENATE(A9," - ",Q9),"") -> Onda 3 - 14 | Q9: =IFERROR(CONCATENATE(IF(OR(E9=1,E9=2),CONCAT("DOCA ",E9),E9)),"") -> 14 | R9: =C9 -> P12_AM1 | S9: =D9 -> AM1_42 | T9: =A9:A454 -> Onda 3
A10: Onda 3 | B10: 503162052001 | C10: Q1_AM1 | D10: AM1_4 | E10: 15 | F10: FLASHLOG | G10: SDDPLL2C41 | H10: Utilitários SDD | J10: Distante | K10: 202 | L10: AM1 - C 6 | P10: =IFERROR(CONCATENATE(A10," - ",Q10),"") -> Onda 3 - 15 | Q10: =IFERROR(CONCATENATE(IF(OR(E10=1,E10=2),CONCAT("DOCA ",E10),E10)),"") -> 15 | R10: =C10 -> Q1_AM1 | S10: =D10 -> AM1_4 | T10: =A10:A455 -> Onda 3
A11: Onda 3 | B11: 503162052005 | C11: Q10_AM1 | D11: AM1_8 | E11: 16 | F11: FLASHLOG | G11: SDDRMN8E33 | H11: Utilitario Fixo | J11: Distante | K11: 98 | L11: AM1 - C 6 | P11: =IFERROR(CONCATENATE(A11," - ",Q11),"") -> Onda 3 - 16 | Q11: =IFERROR(CONCATENATE(IF(OR(E11=1,E11=2),CONCAT("DOCA ",E11),E11)),"") -> 16 | R11: =C11 -> Q10_AM1 | S11: =D11 -> AM1_8 | T11: =A11:A456 -> Onda 3
A12: Onda 3 | B12: 503162052006 | C12: P5_AM1 | D12: AM1_9 | E12: 17 | F12: FLASHLOG | G12: QOC6D66 | H12: Utilitario Fixo | J12: Distante | K12: 106 | L12: AM1 - C 6 | P12: =IFERROR(CONCATENATE(A12," - ",Q12),"") -> Onda 3 - 17 | Q12: =IFERROR(CONCATENATE(IF(OR(E12=1,E12=2),CONCAT("DOCA ",E12),E12)),"") -> 17 | R12: =C12 -> P5_AM1 | S12: =D12 -> AM1_9 | T12: =A12:A457 -> Onda 3
A13: Onda 3 | B13: 503162209005 | C13: P7_AM1 | D13: AM1_19 | E13: 18 | F13: PARCEIRO SPOT SOLUCOES | G13: TEB5J19 | H13: Van Vamos 2025 | J13: Distante - Comercial | K13: 96 | L13: AM1 - C 8 | P13: =IFERROR(CONCATENATE(A13," - ",Q13),"") -> Onda 3 - 18 | Q13: =IFERROR(CONCATENATE(IF(OR(E13=1,E13=2),CONCAT("DOCA ",E13),E13)),"") -> 18 | R13: =C13 -> P7_AM1 | S13: =D13 -> AM1_19 | T13: =A13:A458 -> Onda 3
A14: Onda 3 | B14: 503162096001 | C14: VN6_AM1 | D14: AM1_3 | E14: 19 | F14: PARCEIRO SPOT SOLUCOES | G14: TEB5J16 | H14: Van Vamos 2025 | I14: Híbrida | J14: Distante | K14: 310 | L14: AM1 - C 7 | P14: =IFERROR(CONCATENATE(A14," - ",Q14),"") -> Onda 3 - 19 | Q14: =IFERROR(CONCATENATE(IF(OR(E14=1,E14=2),CONCAT("DOCA ",E14),E14)),"") -> 19 | R14: =C14 -> VN6_AM1 | S14: =D14 -> AM1_3 | T14: =A14:A459 -> Onda 3
A15: Onda 3 | B15: 503162052002 | C15: Q5_AM1 | D15: AM1_5 | E15: 20 | F15: PARCEIRO SPOT SOLUCOES | G15: TEB5J14 | H15: Van Vamos 2025 | J15: Comercial - Distante | K15: 119 | L15: AM1 - C 6 | P15: =IFERROR(CONCATENATE(A15," - ",Q15),"") -> Onda 3 - 20 | Q15: =IFERROR(CONCATENATE(IF(OR(E15=1,E15=2),CONCAT("DOCA ",E15),E15)),"") -> 20 | R15: =C15 -> Q5_AM1 | S15: =D15 -> AM1_5 | T15: =A15:A460 -> Onda 3
A16: Onda 3 | B16: 503162211009 | C16: P4_AM1 | D16: AM1_65 | E16: 21 | F16: A L C TRANSPORTES | G16: PWK9B31 | H16: Utilitários | J16: Comercial - Distante | K16: 108 | L16: AM1 - C 2 | P16: =IFERROR(CONCATENATE(A16," - ",Q16),"") -> Onda 3 - 21 | Q16: =IFERROR(CONCATENATE(IF(OR(E16=1,E16=2),CONCAT("DOCA ",E16),E16)),"") -> 21 | R16: =C16 -> P4_AM1 | S16: =D16 -> AM1_65 | T16: =A16:A461 -> Onda 3
A17: Onda 3 | B17: 503162210007 | C17: P8_AM1 | D17: AM1_43 | E17: 22 | F17: A L C TRANSPORTES | G17: SDDRMS8F61 | H17: Utilitários SDD | J17: Comercial - Distante | K17: 94 | L17: AM1 - C 3 | P17: =IFERROR(CONCATENATE(A17," - ",Q17),"") -> Onda 3 - 22 | Q17: =IFERROR(CONCATENATE(IF(OR(E17=1,E17=2),CONCAT("DOCA ",E17),E17)),"") -> 22 | R17: =C17 -> P8_AM1 | S17: =D17 -> AM1_43 | T17: =A17:A462 -> Onda 3
A18: Onda 3 | B18: 503162211002 | C18: Q8_AM1 | D18: AM1_58 | E18: 23 | F18: A L C TRANSPORTES | G18: SDDPVK4C55 | H18: Utilitários SDD | J18: Comercial - Distante | K18: 108 | L18: AM1 - C 2 | P18: =IFERROR(CONCATENATE(A18," - ",Q18),"") -> Onda 3 - 23 | Q18: =IFERROR(CONCATENATE(IF(OR(E18=1,E18=2),CONCAT("DOCA ",E18),E18)),"") -> 23 | R18: =C18 -> Q8_AM1 | S18: =D18 -> AM1_58 | T18: =A18:A463 -> Onda 3
A19: Onda 3 | B19: 503162211014 | C19: P2_AM1 | D19: AM1_70 | E19: 24 | F19: HELP ME SOLUCOES | G19: SYZ5B99 | H19: Utilitários | J19: Comercial - Distante | K19: 130 | L19: AM1 - C 2 | P19: =IFERROR(CONCATENATE(A19," - ",Q19),"") -> Onda 3 - 24 | Q19: =IFERROR(CONCATENATE(IF(OR(E19=1,E19=2),CONCAT("DOCA ",E19),E19)),"") -> 24 | R19: =C19 -> P2_AM1 | S19: =D19 -> AM1_70 | T19: =A19:A464 -> Onda 3
A20: Onda 3 | B20: 503162211013 | C20: Q6_AM1 | D20: AM1_69 | E20: 25 | F20: HELP ME SOLUCOES | G20: RNK7H96 | H20: Utilitários | J20: Comercial - Distante | K20: 115 | L20: AM1 - C 2 | P20: =IFERROR(CONCATENATE(A20," - ",Q20),"") -> Onda 3 - 25 | Q20: =IFERROR(CONCATENATE(IF(OR(E20=1,E20=2),CONCAT("DOCA ",E20),E20)),"") -> 25 | R20: =C20 -> Q6_AM1 | S20: =D20 -> AM1_69 | T20: =A20:A465 -> Onda 3
A21: Onda 3 | B21: 503162052003 | C21: P3_AM1 | D21: AM1_6 | E21: 26 | F21: FLASHLOG | G21: PYU9C17 | H21: Utilitario Fixo | J21: Comercial - Distante | K21: 118 | L21: AM1 - C 6 | P21: =IFERROR(CONCATENATE(A21," - ",Q21),"") -> Onda 3 - 26 | Q21: =IFERROR(CONCATENATE(IF(OR(E21=1,E21=2),CONCAT("DOCA ",E21),E21)),"") -> 26 | R21: =C21 -> P3_AM1 | S21: =D21 -> AM1_6 | T21: =A21:A466 -> Onda 3
A22: Onda 3 | B22: 503162052004 | C22: P9_AM1 | D22: AM1_7 | E22: 27 | F22: FLASHLOG | G22: AZN3B80 | H22: Utilitario Fixo | J22: Distante - Comercial | K22: 92 | L22: AM1 - C 6 | P22: =IFERROR(CONCATENATE(A22," - ",Q22),"") -> Onda 3 - 27 | Q22: =IFERROR(CONCATENATE(IF(OR(E22=1,E22=2),CONCAT("DOCA ",E22),E22)),"") -> 27 | R22: =C22 -> P9_AM1 | S22: =D22 -> AM1_7 | T22: =A22:A467 -> Onda 3
A23: Onda 3 | B23: 503162052008 | C23: Q9_AM1 | D23: AM1_11 | E23: 28 | F23: FLASHLOG | G23: SDDNLR1E03 | H23: Utilitario Fixo | J23: Comercial - Distante | K23: 106 | L23: AM1 - C 6 | P23: =IFERROR(CONCATENATE(A23," - ",Q23),"") -> Onda 3 - 28 | Q23: =IFERROR(CONCATENATE(IF(OR(E23=1,E23=2),CONCAT("DOCA ",E23),E23)),"") -> 28 | R23: =C23 -> Q9_AM1 | S23: =D23 -> AM1_11 | T23: =A23:A468 -> Onda 3
A24: Onda 3 | B24: 503162052009 | C24: Q4_AM1 | D24: AM1_12 | E24: 29 | F24: FLASHLOG | G24: SDDFLT2F40 | H24: Utilitario Fixo | J24: Comercial - Distante | K24: 124 | L24: AM1 - C 6 | P24: =IFERROR(CONCATENATE(A24," - ",Q24),"") -> Onda 3 - 29 | Q24: =IFERROR(CONCATENATE(IF(OR(E24=1,E24=2),CONCAT("DOCA ",E24),E24)),"") -> 29 | R24: =C24 -> Q4_AM1 | S24: =D24 -> AM1_12 | T24: =A24:A469 -> Onda 3
A25: Onda 3 | B25: 503162210001 | C25: P13_AM1 | D25: AM1_37 | E25: 30 | F25: Kangu Logistics | G25: QYO6J12 | H25: Utilitários SDD | J25: Comercial - Distante | K25: 68 | L25: AM1 - C 3 | P25: =IFERROR(CONCATENATE(A25," - ",Q25),"") -> Onda 3 - 30 | Q25: =IFERROR(CONCATENATE(IF(OR(E25=1,E25=2),CONCAT("DOCA ",E25),E25)),"") -> 30 | R25: =C25 -> P13_AM1 | S25: =D25 -> AM1_37 | T25: =A25:A470 -> Onda 3
A26: Onda 4 | B26: 503162211007 | C26: VM8_AM1 | D26: AM1_63 | E26: 1 | F26: PARCEIRO SPOT SOLUCOES | G26: TXY6A60 | H26: Vuc Vamos 2025 | I26: Híbrida | J26: Distante - Comercial | K26: 121 | L26: AM1 - C 2 | P26: =IFERROR(CONCATENATE(A26," - ",Q26),"") -> Onda 4 - DOCA 1 | Q26: =IFERROR(CONCATENATE(IF(OR(E26=1,E26=2),CONCAT("DOCA ",E26),E26)),"") -> DOCA 1 | R26: =C26 -> VM8_AM1 | S26: =D26 -> AM1_63 | T26: =A26:A471 -> Onda 4
A27: Onda 4 | B27: 503162211006 | C27: VN1_AM1 | D27: AM1_62 | E27: 2 | F27: PARCEIRO SPOT SOLUCOES | G27: TEN6A96 | H27: Vuc Vamos 2025 | I27: Híbrida | J27: Distante - Comercial | K27: 167 | L27: AM1 - C 2 | P27: =IFERROR(CONCATENATE(A27," - ",Q27),"") -> Onda 4 - DOCA 2 | Q27: =IFERROR(CONCATENATE(IF(OR(E27=1,E27=2),CONCAT("DOCA ",E27),E27)),"") -> DOCA 2 | R27: =C27 -> VN1_AM1 | S27: =D27 -> AM1_62 | T27: =A27:A472 -> Onda 4
A28: Onda 4 | B28: 503162697004 | C28: A7_AM1 | D28: AM1_116 | E28: 9 | F28: PARCEIRO SPOT SOLUCOES | G28: TEC1G20 | H28: Vuc Vamos 2025 | K28: 120 | L28: AM1 - C 4 | P28: =IFERROR(CONCATENATE(A28," - ",Q28),"") -> Onda 4 - 9 | Q28: =IFERROR(CONCATENATE(IF(OR(E28=1,E28=2),CONCAT("DOCA ",E28),E28)),"") -> 9 | R28: =C28 -> A7_AM1 | S28: =D28 -> AM1_116 | T28: =A28:A473 -> Onda 4
A29: Onda 4 | B29: 503162211012 | C29: Q3_AM1 | D29: AM1_68 | E29: 10 | F29: Hawk Transportes | G29: TZB1I38 | H29: Utilitários | J29: Comercial - Distante | K29: 137 | L29: AM1 - C 2 | P29: =IFERROR(CONCATENATE(A29," - ",Q29),"") -> Onda 4 - 10 | Q29: =IFERROR(CONCATENATE(IF(OR(E29=1,E29=2),CONCAT("DOCA ",E29),E29)),"") -> 10 | R29: =C29 -> Q3_AM1 | S29: =D29 -> AM1_68 | T29: =A29:A474 -> Onda 4
A30: Onda 4 | B30: 503162209008 | C30: H11_AM1 | D30: AM1_22 | E30: 11 | F30: Hawk Transportes | G30: QPW5D28 | H30: Utilitários | J30: Comercial - Distante | K30: 91 | L30: AM1 - C 8 | P30: =IFERROR(CONCATENATE(A30," - ",Q30),"") -> Onda 4 - 11 | Q30: =IFERROR(CONCATENATE(IF(OR(E30=1,E30=2),CONCAT("DOCA ",E30),E30)),"") -> 11 | R30: =C30 -> H11_AM1 | S30: =D30 -> AM1_22 | T30: =A30:A475 -> Onda 4
A31: Onda 4 | B31: 503162211001 | C31: I8_AM1 | D31: AM1_57 | E31: 12 | F31: Hawk Transportes | G31: SDDBCM9G31 | H31: Utilitários SDD | J31: Comercial - Distante | K31: 113 | L31: AM1 - C 2 | P31: =IFERROR(CONCATENATE(A31," - ",Q31),"") -> Onda 4 - 12 | Q31: =IFERROR(CONCATENATE(IF(OR(E31=1,E31=2),CONCAT("DOCA ",E31),E31)),"") -> 12 | R31: =C31 -> I8_AM1 | S31: =D31 -> AM1_57 | T31: =A31:A476 -> Onda 4
A32: Onda 4 | B32: 503162697008 | C32: A8_AM1 | D32: AM1_120 | E32: 13 | F32: Hawk Transportes | G32: QUC4744 | H32: Utilitários | J32: Comercial | K32: 105 | L32: AM1 - C 4 | P32: =IFERROR(CONCATENATE(A32," - ",Q32),"") -> Onda 4 - 13 | Q32: =IFERROR(CONCATENATE(IF(OR(E32=1,E32=2),CONCAT("DOCA ",E32),E32)),"") -> 13 | R32: =C32 -> A8_AM1 | S32: =D32 -> AM1_120 | T32: =A32:A477 -> Onda 4
A33: Onda 4 | B33: 503162367010 | C33: B3_AM1 | D33: AM1_111 | E33: 14 | F33: Hawk Transportes | G33: PAK2D47 | H33: Utilitários | J33: Comercial | K33: 134 | L33: AM1 - C 5 | P33: =IFERROR(CONCATENATE(A33," - ",Q33),"") -> Onda 4 - 14 | Q33: =IFERROR(CONCATENATE(IF(OR(E33=1,E33=2),CONCAT("DOCA ",E33),E33)),"") -> 14 | R33: =C33 -> B3_AM1 | S33: =D33 -> AM1_111 | T33: =A33:A478 -> Onda 4
A34: Onda 4 | B34: 503162697003 | C34: B1_AM1 | D34: AM1_115 | E34: 15 | F34: PARCEIRO SPOT SOLUCOES | G34: RUM2B41 | H34: Rental Utilitário com Ajudante | J34: Comercial | K34: 160 | L34: AM1 - C 4 | P34: =IFERROR(CONCATENATE(A34," - ",Q34),"") -> Onda 4 - 15 | Q34: =IFERROR(CONCATENATE(IF(OR(E34=1,E34=2),CONCAT("DOCA ",E34),E34)),"") -> 15 | R34: =C34 -> B1_AM1 | S34: =D34 -> AM1_115 | T34: =A34:A479 -> Onda 4
A35: Onda 4 | B35: 503162211003 | C35: Q7_AM1 | D35: AM1_59 | E35: 16 | F35: PARCEIRO SPOT SOLUCOES | G35: TDZ7B97 | H35: Van Vamos 2025 | J35: Distante | K35: 115 | L35: AM1 - C 2 | P35: =IFERROR(CONCATENATE(A35," - ",Q35),"") -> Onda 4 - 16 | Q35: =IFERROR(CONCATENATE(IF(OR(E35=1,E35=2),CONCAT("DOCA ",E35),E35)),"") -> 16 | R35: =C35 -> Q7_AM1 | S35: =D35 -> AM1_59 | T35: =A35:A480 -> Onda 4
A36: Onda 4 | B36: 503162697007 | C36: A9_AM1 | D36: AM1_119 | E36: 17 | F36: PARCEIRO SPOT SOLUCOES | G36: TBK9F54 | H36: Utilitário Arval 2025 | J36: Comercial | K36: 58 | L36: AM1 - C 4 | P36: =IFERROR(CONCATENATE(A36," - ",Q36),"") -> Onda 4 - 17 | Q36: =IFERROR(CONCATENATE(IF(OR(E36=1,E36=2),CONCAT("DOCA ",E36),E36)),"") -> 17 | R36: =C36 -> A9_AM1 | S36: =D36 -> AM1_119 | T36: =A36:A481 -> Onda 4
A37: Onda 4 | B37: 503162209001 | C37: D1_AM1 | D37: AM1_15 | E37: 18 | F37: Hawk Transportes | G37: QNX0J66 | H37: Vuc | I37: Híbrida | J37: Comercial - Distante | K37: 393 | L37: AM1 - C 8 | P37: =IFERROR(CONCATENATE(A37," - ",Q37),"") -> Onda 4 - 18 | Q37: =IFERROR(CONCATENATE(IF(OR(E37=1,E37=2),CONCAT("DOCA ",E37),E37)),"") -> 18 | R37: =C37 -> D1_AM1 | S37: =D37 -> AM1_15 | T37: =A37:A482 -> Onda 4
A38: Onda 4 | B38: 503162211004 | C38: I1_AM1 | D38: AM1_60 | E38: 19 | F38: PARCEIRO SPOT SOLUCOES | G38: TEB5I99 | H38: Van Vamos 2025 | J38: Comercial - Distante | K38: 154 | L38: AM1 - C 2 | P38: =IFERROR(CONCATENATE(A38," - ",Q38),"") -> Onda 4 - 19 | Q38: =IFERROR(CONCATENATE(IF(OR(E38=1,E38=2),CONCAT("DOCA ",E38),E38)),"") -> 19 | R38: =C38 -> I1_AM1 | S38: =D38 -> AM1_60 | T38: =A38:A483 -> Onda 4
A39: Onda 4 | B39: 503162367009 | C39: B2_AM1 | D39: AM1_110 | E39: 20 | F39: PARCEIRO SPOT SOLUCOES | G39: TBK9D25 | H39: Utilitário Arval 2025 | J39: Comercial | K39: 152 | L39: AM1 - C 5 | P39: =IFERROR(CONCATENATE(A39," - ",Q39),"") -> Onda 4 - 20 | Q39: =IFERROR(CONCATENATE(IF(OR(E39=1,E39=2),CONCAT("DOCA ",E39),E39)),"") -> 20 | R39: =C39 -> B2_AM1 | S39: =D39 -> AM1_110 | T39: =A39:A484 -> Onda 4
A40: Onda 4 | B40: 503162697012 | C40: A4_AM1 | D40: AM1_124 | E40: 21 | F40: A L C TRANSPORTES | G40: OXH2C13 | H40: Utilitários | J40: Comercial | K40: 130 | L40: AM1 - C 4 | P40: =IFERROR(CONCATENATE(A40," - ",Q40),"") -> Onda 4 - 21 | Q40: =IFERROR(CONCATENATE(IF(OR(E40=1,E40=2),CONCAT("DOCA ",E40),E40)),"") -> 21 | R40: =C40 -> A4_AM1 | S40: =D40 -> AM1_124 | T40: =A40:A485 -> Onda 4
...

Sheet Filipeta
A1: =TODAY() -> 46265 | E1: FILIPETA DE CARREGAMENTO | I1: FILIPETA DE CARREGAMENTO | N1: FILIPETA DE CARREGAMENTO | R1: FILIPETA DE CARREGAMENTO | V1: FILIPETA DE CARREGAMENTO | Z1: FILIPETA DE CARREGAMENTO | AD1: FILIPETA DE CARREGAMENTO
A2: VAGA | B2: NOME | C2: Suporte XPT | D2: P.S. | E2: 1ª ONDA | I2: 2ª ONDA | N2: 3ª ONDA | R2: 4ª ONDA | V2: 5ª ONDA | Z2: 6ª ONDA | AD2: 7ª ONDA
E3: Rota Expedição | F3: Rota Romaneio | G3: T | H3: Linha Branca | I3: Rota Expedição | J3: Rota Romaneio | K3: T | L3: Linha Branca | M3: VAGA | N3: Rota Expedição | O3: Rota Romaneio | P3: T | Q3: Linha Branca | R3: Rota Expedição | S3: Rota Romaneio | T3: T | U3: Linha Branca | V3: Rota Expedição | W3: Rota Romaneio | X3: T | Y3: Linha Branca | Z3: Rota Expedição | AA3: Rota Romaneio | AB3: T | AC3: Linha Branca | AD3: Rota Expedição | AE3: Rota Romaneio | AF3: T | AG3: Linha Branca
A4: YMS-S | E4: - | F4: - | G4: - | I4: - | J4: - | K4: - | N4: - | O4: - | P4: - | R4: - | S4: - | T4: - | V4: - | W4: - | X4: - | Z4: - | AA4: - | AB4: - | AD4: - | AE4: - | AF4: - | AG4: -
A5: YMS-E | E5: - | F5: - | G5: - | I5: - | J5: - | K5: - | N5: - | O5: - | P5: - | R5: - | S5: - | T5: - | V5: - | W5: - | X5: - | Z5: - | AA5: - | AB5: - | AD5: - | AE5: - | AF5: - | AG5: -
A6: PÓS SORTING
A7: DOCA 1 | E7: =IFERROR(VLOOKUP(CONCATENATE("Onda 1"," - ",A7),'Dist expedição'!P:S,3,0),"") | F7: =IFERROR(VLOOKUP(E7,'Dist expedição'!$C:$E,2,0),"") | G7: =IFERROR(VLOOKUP(E7,'Dist expedição'!$C:$F,4,0),"") | H7: =IF(E7="", "", IF(ISNUMBER(MATCH(SUBSTITUTE(E7, "_AM1", ""), 'Resumo Mapa'!A:A, 0)), "✅", "❌")) | I7: =IFERROR(VLOOKUP(CONCATENATE("Onda 2"," - ",A7),'Dist expedição'!P:S,3,0),"") | J7: =IFERROR(VLOOKUP(I7,'Dist expedição'!$C:$E,2,0),"") | K7: =IFERROR(VLOOKUP(I7,'Dist expedição'!$C:$F,4,0),"") | L7: =IF(I7="", "", IF(ISNUMBER(MATCH(SUBSTITUTE(I7, "_AM1", ""), 'Resumo Mapa'!A:A, 0)), "✅", "❌")) | M7: DOCA 1 | N7: =IFERROR(VLOOKUP(CONCATENATE("Onda 3"," - ",A7),'Dist expedição'!P:S,3,0),"") -> VM9_AM1 | O7: =IFERROR(VLOOKUP(N7,'Dist expedição'!$C:$E,2,0),"") -> AM1_52 | P7: =IFERROR(VLOOKUP(N7,'Dist expedição'!$C:$F,4,0),"") -> PARCEIRO SPOT SOLUCOES | Q7: =IF(N7="", "", IF(ISNUMBER(MATCH(SUBSTITUTE(N7, "_AM1", ""), 'Resumo Mapa'!A:A, 0)), "✅", "❌")) -> ✅ | R7: =IFERROR(VLOOKUP(CONCATENATE("Onda 4"," - ",A7),'Dist expedição'!P:S,3,0),"") -> VM8_AM1 | S7: =IFERROR(VLOOKUP(R7,'Dist expedição'!$C:$E,2,0),"") -> AM1_63 | T7: =IFERROR(VLOOKUP(R7,'Dist expedição'!$C:$F,4,0),"") -> PARCEIRO SPOT SOLUCOES | U7: =IF(R7="", "", IF(ISNUMBER(MATCH(SUBSTITUTE(R7, "_AM1", ""), 'Resumo Mapa'!A:A, 0)), "✅", "❌")) -> ✅ | V7: =IFERROR(VLOOKUP(CONCATENATE("Onda 5"," - ",A7),'Dist expedição'!P:S,3,0),"") | W7: =IFERROR(VLOOKUP(V7,'Dist expedição'!$C:$E,2,0),"") | X7: =IFERROR(VLOOKUP(V7,'Dist expedição'!$C:$F,4,0),"") | Y7: =IF(V7="", "", IF(ISNUMBER(MATCH(SUBSTITUTE(V7, "_AM1", ""), 'Resumo Mapa'!A:A, 0)), "✅", "❌")) | Z7: =IFERROR(VLOOKUP(CONCATENATE("Onda 6"," - ",A7),'Dist expedição'!P:S,3,0),"") -> VM10_AM1 | AA7: =IFERROR(VLOOKUP(Z7,'Dist expedição'!$C:$E,2,0),"") -> AM1_13 | AB7: =IFERROR(VLOOKUP(Z7,'Dist expedição'!$C:$F,4,0),"") -> PARCEIRO SPOT SOLUCOES | AC7: =IF(Z7="", "", IF(ISNUMBER(MATCH(SUBSTITUTE(Z7, "_AM1", ""), 'Resumo Mapa'!A:A, 0)), "✅", "❌")) -> ✅ | AD7: =IFERROR(VLOOKUP(CONCATENATE("Onda 7"," - ",A7),'Dist expedição'!P:S,3,0),"") | AE7: =IFERROR(VLOOKUP(AD7,'Dist expedição'!$C:$E,2,0),"") | AF7: =IFERROR(VLOOKUP(AD7,'Dist expedição'!$C:$F,4,0),"") | AG7: =IF(AD7="", "", IF(ISNUMBER(MATCH(SUBSTITUTE(AD7, "_AM1", ""), 'Resumo Mapa'!A:A, 0)), "✅", "❌"))
A8: DOCA 2 | E8: =IFERROR(VLOOKUP(CONCATENATE("Onda 1"," - ",A8),'Dist expedição'!P:S,3,0),"") | F8: =IFERROR(VLOOKUP(E8,'Dist expedição'!$C:$E,2,0),"") | G8: =IFERROR(VLOOKUP(E8,'Dist expedição'!$C:$F,4,0),"") | H8: =IF(E8="", "", IF(ISNUMBER(MATCH(SUBSTITUTE(E8, "_AM1", ""), 'Resumo Mapa'!A:A, 0)), "✅", "❌")) | I8: =IFERROR(VLOOKUP(CONCATENATE("Onda 2"," - ",A8),'Dist expedição'!P:S,3,0),"") | J8: =IFERROR(VLOOKUP(I8,'Dist expedição'!$C:$E,2,0),"") | K8: =IFERROR(VLOOKUP(I8,'Dist expedição'!$C:$F,4,0),"") | L8: =IF(I8="", "", IF(ISNUMBER(MATCH(SUBSTITUTE(I8, "_AM1", ""), 'Resumo Mapa'!A:A, 0)), "✅", "❌")) | M8: DOCA 2 | N8: =IFERROR(VLOOKUP(CONCATENATE("Onda 3"," - ",A8),'Dist expedição'!P:S,3,0),"") -> VN7_AM1 | O8: =IFERROR(VLOOKUP(N8,'Dist expedição'!$C:$E,2,0),"") -> AM1_64 | P8: =IFERROR(VLOOKUP(N8,'Dist expedição'!$C:$F,4,0),"") -> PARCEIRO SPOT SOLUCOES | Q8: =IF(N8="", "", IF(ISNUMBER(MATCH(SUBSTITUTE(N8, "_AM1", ""), 'Resumo Mapa'!A:A, 0)), "✅", "❌")) -> ✅ | R8: =IFERROR(VLOOKUP(CONCATENATE("Onda 4"," - ",A8),'Dist expedição'!P:S,3,0),"") -> VN1_AM1 | S8: =IFERROR(VLOOKUP(R8,'Dist expedição'!$C:$E,2,0),"") -> AM1_62 | T8: =IFERROR(VLOOKUP(R8,'Dist expedição'!$C:$F,4,0),"") -> PARCEIRO SPOT SOLUCOES | U8: =IF(R8="", "", IF(ISNUMBER(MATCH(SUBSTITUTE(R8, "_AM1", ""), 'Resumo Mapa'!A:A, 0)), "✅", "❌")) -> ✅ | V8: =IFERROR(VLOOKUP(CONCATENATE("Onda 5"," - ",A8),'Dist expedição'!P:S,3,0),"") | W8: =IFERROR(VLOOKUP(V8,'Dist expedição'!$C:$E,2,0),"") | X8: =IFERROR(VLOOKUP(V8,'Dist expedição'!$C:$F,4,0),"") | Y8: =IF(V8="", "", IF(ISNUMBER(MATCH(SUBSTITUTE(V8, "_AM1", ""), 'Resumo Mapa'!A:A, 0)), "✅", "❌")) | Z8: =IFERROR(VLOOKUP(CONCATENATE("Onda 6"," - ",A8),'Dist expedição'!P:S,3,0),"") -> VM11_AM1 | AA8: =IFERROR(VLOOKUP(Z8,'Dist expedição'!$C:$E,2,0),"") -> AM1_20 | AB8: =IFERROR(VLOOKUP(Z8,'Dist expedição'!$C:$F,4,0),"") -> PARCEIRO SPOT SOLUCOES | AC8: =IF(Z8="", "", IF(ISNUMBER(MATCH(SUBSTITUTE(Z8, "_AM1", ""), 'Resumo Mapa'!A:A, 0)), "✅", "❌")) -> ✅ | AD8: =IFERROR(VLOOKUP(CONCATENATE("Onda 7"," - ",A8),'Dist expedição'!P:S,3,0),"") | AE8: =IFERROR(VLOOKUP(AD8,'Dist expedição'!$C:$E,2,0),"") | AF8: =IFERROR(VLOOKUP(AD8,'Dist expedição'!$C:$F,4,0),"") | AG8: =IF(AD8="", "", IF(ISNUMBER(MATCH(SUBSTITUTE(AD8, "_AM1", ""), 'Resumo Mapa'!A:A, 0)), "✅", "❌"))
A9: 1 | E9: =IFERROR(VLOOKUP(CONCATENATE("Onda 1"," - ",A9),'Dist expedição'!P:S,3,0),"") | F9: =IFERROR(VLOOKUP(E9,'Dist expedição'!$C:$E,2,0),"") | G9: =IFERROR(VLOOKUP(E9,'Dist expedição'!$C:$F,4,0),"") | H9: =IF(E9="", "", IF(ISNUMBER(MATCH(SUBSTITUTE(E9, "_AM1", ""), 'Resumo Mapa'!A:A, 0)), "✅", "❌")) | I9: =IFERROR(VLOOKUP(CONCATENATE("Onda 2"," - ",A9),'Dist expedição'!P:S,3,0),"") | J9: =IFERROR(VLOOKUP(I9,'Dist expedição'!$C:$E,2,0),"") | K9: =IFERROR(VLOOKUP(I9,'Dist expedição'!$C:$F,4,0),"") | L9: =IF(I9="", "", IF(ISNUMBER(MATCH(SUBSTITUTE(I9, "_AM1", ""), 'Resumo Mapa'!A:A, 0)), "✅", "❌")) | M9: 1 | N9: =IFERROR(VLOOKUP(CONCATENATE("Onda 3"," - ",A9),'Dist expedição'!P:S,3,0),"") | O9: =IFERROR(VLOOKUP(N9,'Dist expedição'!$C:$E,2,0),"") | P9: =IFERROR(VLOOKUP(N9,'Dist expedição'!$C:$F,4,0),"") | Q9: =IF(N9="", "", IF(ISNUMBER(MATCH(SUBSTITUTE(N9, "_AM1", ""), 'Resumo Mapa'!A:A, 0)), "✅", "❌")) | R9: =IFERROR(VLOOKUP(CONCATENATE("Onda 4"," - ",A9),'Dist expedição'!P:S,3,0),"") | S9: =IFERROR(VLOOKUP(R9,'Dist expedição'!$C:$E,2,0),"") | T9: =IFERROR(VLOOKUP(R9,'Dist expedição'!$C:$F,4,0),"") | U9: =IF(R9="", "", IF(ISNUMBER(MATCH(SUBSTITUTE(R9, "_AM1", ""), 'Resumo Mapa'!A:A, 0)), "✅", "❌")) | V9: =IFERROR(VLOOKUP(CONCATENATE("Onda 5"," - ",A9),'Dist expedição'!P:S,3,0),"") | W9: =IFERROR(VLOOKUP(V9,'Dist expedição'!$C:$E,2,0),"") | X9: =IFERROR(VLOOKUP(V9,'Dist expedição'!$C:$F,4,0),"") | Y9: =IF(V9="", "", IF(ISNUMBER(MATCH(SUBSTITUTE(V9, "_AM1", ""), 'Resumo Mapa'!A:A, 0)), "✅", "❌")) | Z9: =IFERROR(VLOOKUP(CONCATENATE("Onda 6"," - ",A9),'Dist expedição'!P:S,3,0),"") | AA9: =IFERROR(VLOOKUP(Z9,'Dist expedição'!$C:$E,2,0),"") | AB9: =IFERROR(VLOOKUP(Z9,'Dist expedição'!$C:$F,4,0),"") | AC9: =IF(Z9="", "", IF(ISNUMBER(MATCH(SUBSTITUTE(Z9, "_AM1", ""), 'Resumo Mapa'!A:A, 0)), "✅", "❌")) | AD9: =IFERROR(VLOOKUP(CONCATENATE("Onda 7"," - ",A9),'Dist expedição'!P:S,3,0),"") | AE9: =IFERROR(VLOOKUP(AD9,'Dist expedição'!$C:$E,2,0),"") | AF9: =IFERROR(VLOOKUP(AD9,'Dist expedição'!$C:$F,4,0),"") | AG9: =IF(AD9="", "", IF(ISNUMBER(MATCH(SUBSTITUTE(AD9, "_AM1", ""), 'Resumo Mapa'!A:A, 0)), "✅", "❌"))
A10: 2 | E10: =IFERROR(VLOOKUP(CONCATENATE("Onda 1"," - ",A10),'Dist expedição'!P:S,3,0),"") | F10: =IFERROR(VLOOKUP(E10,'Dist expedição'!$C:$E,2,0),"") | G10: =IFERROR(VLOOKUP(E10,'Dist expedição'!$C:$F,4,0),"") | H10: =IF(E10="", "", IF(ISNUMBER(MATCH(SUBSTITUTE(E10, "_AM1", ""), 'Resumo Mapa'!A:A, 0)), "✅", "❌")) | I10: =IFERROR(VLOOKUP(CONCATENATE("Onda 2"," - ",A10),'Dist expedição'!P:S,3,0),"") | J10: =IFERROR(VLOOKUP(I10,'Dist expedição'!$C:$E,2,0),"") | K10: =IFERROR(VLOOKUP(I10,'Dist expedição'!$C:$F,4,0),"") | L10: =IF(I10="", "", IF(ISNUMBER(MATCH(SUBSTITUTE(I10, "_AM1", ""), 'Resumo Mapa'!A:A, 0)), "✅", "❌")) | M10: 2 | N10: =IFERROR(VLOOKUP(CONCATENATE("Onda 3"," - ",A10),'Dist expedição'!P:S,3,0),"") | O10: =IFERROR(VLOOKUP(N10,'Dist expedição'!$C:$E,2,0),"") | P10: =IFERROR(VLOOKUP(N10,'Dist expedição'!$C:$F,4,0),"") | Q10: =IF(N10="", "", IF(ISNUMBER(MATCH(SUBSTITUTE(N10, "_AM1", ""), 'Resumo Mapa'!A:A, 0)), "✅", "❌")) | R10: =IFERROR(VLOOKUP(CONCATENATE("Onda 4"," - ",A10),'Dist expedição'!P:S,3,0),"") | S10: =IFERROR(VLOOKUP(R10,'Dist expedição'!$C:$E,2,0),"") | T10: =IFERROR(VLOOKUP(R10,'Dist expedição'!$C:$F,4,0),"") | U10: =IF(R10="", "", IF(ISNUMBER(MATCH(SUBSTITUTE(R10, "_AM1", ""), 'Resumo Mapa'!A:A, 0)), "✅", "❌")) | V10: =IFERROR(VLOOKUP(CONCATENATE("Onda 5"," - ",A10),'Dist expedição'!P:S,3,0),"") | W10: =IFERROR(VLOOKUP(V10,'Dist expedição'!$C:$E,2,0),"") | X10: =IFERROR(VLOOKUP(V10,'Dist expedição'!$C:$F,4,0),"") | Y10: =IF(V10="", "", IF(ISNUMBER(MATCH(SUBSTITUTE(V10, "_AM1", ""), 'Resumo Mapa'!A:A, 0)), "✅", "❌")) | Z10: =IFERROR(VLOOKUP(CONCATENATE("Onda 6"," - ",A10),'Dist expedição'!P:S,3,0),"") | AA10: =IFERROR(VLOOKUP(Z10,'Dist expedição'!$C:$E,2,0),"") | AB10: =IFERROR(VLOOKUP(Z10,'Dist expedição'!$C:$F,4,0),"") | AC10: =IF(Z10="", "", IF(ISNUMBER(MATCH(SUBSTITUTE(Z10, "_AM1", ""), 'Resumo Mapa'!A:A, 0)), "✅", "❌")) | AD10: =IFERROR(VLOOKUP(CONCATENATE("Onda 7"," - ",A10),'Dist expedição'!P:S,3,0),"") | AE10: =IFERROR(VLOOKUP(AD10,'Dist expedição'!$C:$E,2,0),"") | AF10: =IFERROR(VLOOKUP(AD10,'Dist expedição'!$C:$F,4,0),"") | AG10: =IF(AD10="", "", IF(ISNUMBER(MATCH(SUBSTITUTE(AD10, "_AM1", ""), 'Resumo Mapa'!A:A, 0)), "✅", "❌"))
A11: 3 | E11: =IFERROR(VLOOKUP(CONCATENATE("Onda 1"," - ",A11),'Dist expedição'!P:S,3,0),"") | F11: =IFERROR(VLOOKUP(E11,'Dist expedição'!$C:$E,2,0),"") | G11: =IFERROR(VLOOKUP(E11,'Dist expedição'!$C:$F,4,0),"") | H11: =IF(E11="", "", IF(ISNUMBER(MATCH(SUBSTITUTE(E11, "_AM1", ""), 'Resumo Mapa'!A:A, 0)), "✅", "❌")) | I11: =IFERROR(VLOOKUP(CONCATENATE("Onda 2"," - ",A11),'Dist expedição'!P:S,3,0),"") | J11: =IFERROR(VLOOKUP(I11,'Dist expedição'!$C:$E,2,0),"") | K11: =IFERROR(VLOOKUP(I11,'Dist expedição'!$C:$F,4,0),"") | L11: =IF(I11="", "", IF(ISNUMBER(MATCH(SUBSTITUTE(I11, "_AM1", ""), 'Resumo Mapa'!A:A, 0)), "✅", "❌")) | M11: 3 | N11: =IFERROR(VLOOKUP(CONCATENATE("Onda 3"," - ",A11),'Dist expedição'!P:S,3,0),"") | O11: =IFERROR(VLOOKUP(N11,'Dist expedição'!$C:$E,2,0),"") | P11: =IFERROR(VLOOKUP(N11,'Dist expedição'!$C:$F,4,0),"") | Q11: =IF(N11="", "", IF(ISNUMBER(MATCH(SUBSTITUTE(N11, "_AM1", ""), 'Resumo Mapa'!A:A, 0)), "✅", "❌")) | R11: =IFERROR(VLOOKUP(CONCATENATE("Onda 4"," - ",A11),'Dist expedição'!P:S,3,0),"") | S11: =IFERROR(VLOOKUP(R11,'Dist expedição'!$C:$E,2,0),"") | T11: =IFERROR(VLOOKUP(R11,'Dist expedição'!$C:$F,4,0),"") | U11: =IF(R11="", "", IF(ISNUMBER(MATCH(SUBSTITUTE(R11, "_AM1", ""), 'Resumo Mapa'!A:A, 0)), "✅", "❌")) | V11: =IFERROR(VLOOKUP(CONCATENATE("Onda 5"," - ",A11),'Dist expedição'!P:S,3,0),"") | W11: =IFERROR(VLOOKUP(V11,'Dist expedição'!$C:$E,2,0),"") | X11: =IFERROR(VLOOKUP(V11,'Dist expedição'!$C:$F,4,0),"") | Y11: =IF(V11="", "", IF(ISNUMBER(MATCH(SUBSTITUTE(V11, "_AM1", ""), 'Resumo Mapa'!A:A, 0)), "✅", "❌")) | Z11: =IFERROR(VLOOKUP(CONCATENATE("Onda 6"," - ",A11),'Dist expedição'!P:S,3,0),"") | AA11: =IFERROR(VLOOKUP(Z11,'Dist expedição'!$C:$E,2,0),"") | AB11: =IFERROR(VLOOKUP(Z11,'Dist expedição'!$C:$F,4,0),"") | AC11: =IF(Z11="", "", IF(ISNUMBER(MATCH(SUBSTITUTE(Z11, "_AM1", ""), 'Resumo Mapa'!A:A, 0)), "✅", "❌")) | AD11: =IFERROR(VLOOKUP(CONCATENATE("Onda 7"," - ",A11),'Dist expedição'!P:S,3,0),"") | AE11: =IFERROR(VLOOKUP(AD11,'Dist expedição'!$C:$E,2,0),"") | AF11: =IFERROR(VLOOKUP(AD11,'Dist expedição'!$C:$F,4,0),"") | AG11: =IF(AD11="", "", IF(ISNUMBER(MATCH(SUBSTITUTE(AD11, "_AM1", ""), 'Resumo Mapa'!A:A, 0)), "✅", "❌"))
A12: 4 | E12: =IFERROR(VLOOKUP(CONCATENATE("Onda 1"," - ",A12),'Dist expedição'!P:S,3,0),"") | F12: =IFERROR(VLOOKUP(E12,'Dist expedição'!$C:$E,2,0),"") | G12: =IFERROR(VLOOKUP(E12,'Dist expedição'!$C:$F,4,0),"") | H12: =IF(E12="", "", IF(ISNUMBER(MATCH(SUBSTITUTE(E12, "_AM1", ""), 'Resumo Mapa'!A:A, 0)), "✅", "❌")) | I12: =IFERROR(VLOOKUP(CONCATENATE("Onda 2"," - ",A12),'Dist expedição'!P:S,3,0),"") | J12: =IFERROR(VLOOKUP(I12,'Dist expedição'!$C:$E,2,0),"") | K12: =IFERROR(VLOOKUP(I12,'Dist expedição'!$C:$F,4,0),"") | L12: =IF(I12="", "", IF(ISNUMBER(MATCH(SUBSTITUTE(I12, "_AM1", ""), 'Resumo Mapa'!A:A, 0)), "✅", "❌")) | M12: 4 | N12: =IFERROR(VLOOKUP(CONCATENATE("Onda 3"," - ",A12),'Dist expedição'!P:S,3,0),"") | O12: =IFERROR(VLOOKUP(N12,'Dist expedição'!$C:$E,2,0),"") | P12: =IFERROR(VLOOKUP(N12,'Dist expedição'!$C:$F,4,0),"") | Q12: =IF(N12="", "", IF(ISNUMBER(MATCH(SUBSTITUTE(N12, "_AM1", ""), 'Resumo Mapa'!A:A, 0)), "✅", "❌")) | R12: =IFERROR(VLOOKUP(CONCATENATE("Onda 4"," - ",A12),'Dist expedição'!P:S,3,0),"") | S12: =IFERROR(VLOOKUP(R12,'Dist expedição'!$C:$E,2,0),"") | T12: =IFERROR(VLOOKUP(R12,'Dist expedição'!$C:$F,4,0),"") | U12: =IF(R12="", "", IF(ISNUMBER(MATCH(SUBSTITUTE(R12, "_AM1", ""), 'Resumo Mapa'!A:A, 0)), "✅", "❌")) | V12: =IFERROR(VLOOKUP(CONCATENATE("Onda 5"," - ",A12),'Dist expedição'!P:S,3,0),"") | W12: =IFERROR(VLOOKUP(V12,'Dist expedição'!$C:$E,2,0),"") | X12: =IFERROR(VLOOKUP(V12,'Dist expedição'!$C:$F,4,0),"") | Y12: =IF(V12="", "", IF(ISNUMBER(MATCH(SUBSTITUTE(V12, "_AM1", ""), 'Resumo Mapa'!A:A, 0)), "✅", "❌")) | Z12: =IFERROR(VLOOKUP(CONCATENATE("Onda 6"," - ",A12),'Dist expedição'!P:S,3,0),"") | AA12: =IFERROR(VLOOKUP(Z12,'Dist expedição'!$C:$E,2,0),"") | AB12: =IFERROR(VLOOKUP(Z12,'Dist expedição'!$C:$F,4,0),"") | AC12: =IF(Z12="", "", IF(ISNUMBER(MATCH(SUBSTITUTE(Z12, "_AM1", ""), 'Resumo Mapa'!A:A, 0)), "✅", "❌")) | AD12: =IFERROR(VLOOKUP(CONCATENATE("Onda 7"," - ",A12),'Dist expedição'!P:S,3,0),"") | AE12: =IFERROR(VLOOKUP(AD12,'Dist expedição'!$C:$E,2,0),"") | AF12: =IFERROR(VLOOKUP(AD12,'Dist expedição'!$C:$F,4,0),"") | AG12: =IF(AD12="", "", IF(ISNUMBER(MATCH(SUBSTITUTE(AD12, "_AM1", ""), 'Resumo Mapa'!A:A, 0)), "✅", "❌"))
A13: 5 | E13: =IFERROR(VLOOKUP(CONCATENATE("Onda 1"," - ",A13),'Dist expedição'!P:S,3,0),"") | F13: =IFERROR(VLOOKUP(E13,'Dist expedição'!$C:$E,2,0),"") | G13: =IFERROR(VLOOKUP(E13,'Dist expedição'!$C:$F,4,0),"") | H13: =IF(E13="", "", IF(ISNUMBER(MATCH(SUBSTITUTE(E13, "_AM1", ""), 'Resumo Mapa'!A:A, 0)), "✅", "❌")) | I13: =IFERROR(VLOOKUP(CONCATENATE("Onda 2"," - ",A13),'Dist expedição'!P:S,3,0),"") | J13: =IFERROR(VLOOKUP(I13,'Dist expedição'!$C:$E,2,0),"") | K13: =IFERROR(VLOOKUP(I13,'Dist expedição'!$C:$F,4,0),"") | L13: =IF(I13="", "", IF(ISNUMBER(MATCH(SUBSTITUTE(I13, "_AM1", ""), 'Resumo Mapa'!A:A, 0)), "✅", "❌")) | M13: 5 | N13: =IFERROR(VLOOKUP(CONCATENATE("Onda 3"," - ",A13),'Dist expedição'!P:S,3,0),"") | O13: =IFERROR(VLOOKUP(N13,'Dist expedição'!$C:$E,2,0),"") | P13: =IFERROR(VLOOKUP(N13,'Dist expedição'!$C:$F,4,0),"") | Q13: =IF(N13="", "", IF(ISNUMBER(MATCH(SUBSTITUTE(N13, "_AM1", ""), 'Resumo Mapa'!A:A, 0)), "✅", "❌")) | R13: =IFERROR(VLOOKUP(CONCATENATE("Onda 4"," - ",A13),'Dist expedição'!P:S,3,0),"") | S13: =IFERROR(VLOOKUP(R13,'Dist expedição'!$C:$E,2,0),"") | T13: =IFERROR(VLOOKUP(R13,'Dist expedição'!$C:$F,4,0),"") | U13: =IF(R13="", "", IF(ISNUMBER(MATCH(SUBSTITUTE(R13, "_AM1", ""), 'Resumo Mapa'!A:A, 0)), "✅", "❌")) | V13: =IFERROR(VLOOKUP(CONCATENATE("Onda 5"," - ",A13),'Dist expedição'!P:S,3,0),"") | W13: =IFERROR(VLOOKUP(V13,'Dist expedição'!$C:$E,2,0),"") | X13: =IFERROR(VLOOKUP(V13,'Dist expedição'!$C:$F,4,0),"") | Y13: =IF(V13="", "", IF(ISNUMBER(MATCH(SUBSTITUTE(V13, "_AM1", ""), 'Resumo Mapa'!A:A, 0)), "✅", "❌")) | Z13: =IFERROR(VLOOKUP(CONCATENATE("Onda 6"," - ",A13),'Dist expedição'!P:S,3,0),"") | AA13: =IFERROR(VLOOKUP(Z13,'Dist expedição'!$C:$E,2,0),"") | AB13: =IFERROR(VLOOKUP(Z13,'Dist expedição'!$C:$F,4,0),"") | AC13: =IF(Z13="", "", IF(ISNUMBER(MATCH(SUBSTITUTE(Z13, "_AM1", ""), 'Resumo Mapa'!A:A, 0)), "✅", "❌")) | AD13: =IFERROR(VLOOKUP(CONCATENATE("Onda 7"," - ",A13),'Dist expedição'!P:S,3,0),"") | AE13: =IFERROR(VLOOKUP(AD13,'Dist expedição'!$C:$E,2,0),"") | AF13: =IFERROR(VLOOKUP(AD13,'Dist expedição'!$C:$F,4,0),"") | AG13: =IF(AD13="", "", IF(ISNUMBER(MATCH(SUBSTITUTE(AD13, "_AM1", ""), 'Resumo Mapa'!A:A, 0)), "✅", "❌"))
A14: 6 | E14: =IFERROR(VLOOKUP(CONCATENATE("Onda 1"," - ",A14),'Dist expedição'!P:S,3,0),"") | F14: =IFERROR(VLOOKUP(E14,'Dist expedição'!$C:$E,2,0),"") | G14: =IFERROR(VLOOKUP(E14,'Dist expedição'!$C:$F,4,0),"") | H14: =IF(E14="", "", IF(ISNUMBER(MATCH(SUBSTITUTE(E14, "_AM1", ""), 'Resumo Mapa'!A:A, 0)), "✅", "❌")) | I14: =IFERROR(VLOOKUP(CONCATENATE("Onda 2"," - ",A14),'Dist expedição'!P:S,3,0),"") | J14: =IFERROR(VLOOKUP(I14,'Dist expedição'!$C:$E,2,0),"") | K14: =IFERROR(VLOOKUP(I14,'Dist expedição'!$C:$F,4,0),"") | L14: =IF(I14="", "", IF(ISNUMBER(MATCH(SUBSTITUTE(I14, "_AM1", ""), 'Resumo Mapa'!A:A, 0)), "✅", "❌")) | M14: 6 | N14: =IFERROR(VLOOKUP(CONCATENATE("Onda 3"," - ",A14),'Dist expedição'!P:S,3,0),"") | O14: =IFERROR(VLOOKUP(N14,'Dist expedição'!$C:$E,2,0),"") | P14: =IFERROR(VLOOKUP(N14,'Dist expedição'!$C:$F,4,0),"") | Q14: =IF(N14="", "", IF(ISNUMBER(MATCH(SUBSTITUTE(N14, "_AM1", ""), 'Resumo Mapa'!A:A, 0)), "✅", "❌")) | R14: =IFERROR(VLOOKUP(CONCATENATE("Onda 4"," - ",A14),'Dist expedição'!P:S,3,0),"") | S14: =IFERROR(VLOOKUP(R14,'Dist expedição'!$C:$E,2,0),"") | T14: =IFERROR(VLOOKUP(R14,'Dist expedição'!$C:$F,4,0),"") | U14: =IF(R14="", "", IF(ISNUMBER(MATCH(SUBSTITUTE(R14, "_AM1", ""), 'Resumo Mapa'!A:A, 0)), "✅", "❌")) | V14: =IFERROR(VLOOKUP(CONCATENATE("Onda 5"," - ",A14),'Dist expedição'!P:S,3,0),"") | W14: =IFERROR(VLOOKUP(V14,'Dist expedição'!$C:$E,2,0),"") | X14: =IFERROR(VLOOKUP(V14,'Dist expedição'!$C:$F,4,0),"") | Y14: =IF(V14="", "", IF(ISNUMBER(MATCH(SUBSTITUTE(V14, "_AM1", ""), 'Resumo Mapa'!A:A, 0)), "✅", "❌")) | Z14: =IFERROR(VLOOKUP(CONCATENATE("Onda 6"," - ",A14),'Dist expedição'!P:S,3,0),"") | AA14: =IFERROR(VLOOKUP(Z14,'Dist expedição'!$C:$E,2,0),"") | AB14: =IFERROR(VLOOKUP(Z14,'Dist expedição'!$C:$F,4,0),"") | AC14: =IF(Z14="", "", IF(ISNUMBER(MATCH(SUBSTITUTE(Z14, "_AM1", ""), 'Resumo Mapa'!A:A, 0)), "✅", "❌")) | AD14: =IFERROR(VLOOKUP(CONCATENATE("Onda 7"," - ",A14),'Dist expedição'!P:S,3,0),"") | AE14: =IFERROR(VLOOKUP(AD14,'Dist expedição'!$C:$E,2,0),"") | AF14: =IFERROR(VLOOKUP(AD14,'Dist expedição'!$C:$F,4,0),"") | AG14: =IF(AD14="", "", IF(ISNUMBER(MATCH(SUBSTITUTE(AD14, "_AM1", ""), 'Resumo Mapa'!A:A, 0)), "✅", "❌"))
A15: 7 | E15: =IFERROR(VLOOKUP(CONCATENATE("Onda 1"," - ",A15),'Dist expedição'!P:S,3,0),"") | F15: =IFERROR(VLOOKUP(E15,'Dist expedição'!$C:$E,2,0),"") | G15: =IFERROR(VLOOKUP(E15,'Dist expedição'!$C:$F,4,0),"") | H15: =IF(E15="", "", IF(ISNUMBER(MATCH(SUBSTITUTE(E15, "_AM1", ""), 'Resumo Mapa'!A:A, 0)), "✅", "❌")) | I15: =IFERROR(VLOOKUP(CONCATENATE("Onda 2"," - ",A15),'Dist expedição'!P:S,3,0),"") | J15: =IFERROR(VLOOKUP(I15,'Dist expedição'!$C:$E,2,0),"") | K15: =IFERROR(VLOOKUP(I15,'Dist expedição'!$C:$F,4,0),"") | L15: =IF(I15="", "", IF(ISNUMBER(MATCH(SUBSTITUTE(I15, "_AM1", ""), 'Resumo Mapa'!A:A, 0)), "✅", "❌")) | M15: 7 | N15: =IFERROR(VLOOKUP(CONCATENATE("Onda 3"," - ",A15),'Dist expedição'!P:S,3,0),"") | O15: =IFERROR(VLOOKUP(N15,'Dist expedição'!$C:$E,2,0),"") | P15: =IFERROR(VLOOKUP(N15,'Dist expedição'!$C:$F,4,0),"") | Q15: =IF(N15="", "", IF(ISNUMBER(MATCH(SUBSTITUTE(N15, "_AM1", ""), 'Resumo Mapa'!A:A, 0)), "✅", "❌")) | R15: =IFERROR(VLOOKUP(CONCATENATE("Onda 4"," - ",A15),'Dist expedição'!P:S,3,0),"") | S15: =IFERROR(VLOOKUP(R15,'Dist expedição'!$C:$E,2,0),"") | T15: =IFERROR(VLOOKUP(R15,'Dist expedição'!$C:$F,4,0),"") | U15: =IF(R15="", "", IF(ISNUMBER(MATCH(SUBSTITUTE(R15, "_AM1", ""), 'Resumo Mapa'!A:A, 0)), "✅", "❌")) | V15: =IFERROR(VLOOKUP(CONCATENATE("Onda 5"," - ",A15),'Dist expedição'!P:S,3,0),"") | W15: =IFERROR(VLOOKUP(V15,'Dist expedição'!$C:$E,2,0),"") | X15: =IFERROR(VLOOKUP(V15,'Dist expedição'!$C:$F,4,0),"") | Y15: =IF(V15="", "", IF(ISNUMBER(MATCH(SUBSTITUTE(V15, "_AM1", ""), 'Resumo Mapa'!A:A, 0)), "✅", "❌")) | Z15: =IFERROR(VLOOKUP(CONCATENATE("Onda 6"," - ",A15),'Dist expedição'!P:S,3,0),"") | AA15: =IFERROR(VLOOKUP(Z15,'Dist expedição'!$C:$E,2,0),"") | AB15: =IFERROR(VLOOKUP(Z15,'Dist expedição'!$C:$F,4,0),"") | AC15: =IF(Z15="", "", IF(ISNUMBER(MATCH(SUBSTITUTE(Z15, "_AM1", ""), 'Resumo Mapa'!A:A, 0)), "✅", "❌")) | AD15: =IFERROR(VLOOKUP(CONCATENATE("Onda 7"," - ",A15),'Dist expedição'!P:S,3,0),"") | AE15: =IFERROR(VLOOKUP(AD15,'Dist expedição'!$C:$E,2,0),"") | AF15: =IFERROR(VLOOKUP(AD15,'Dist expedição'!$C:$F,4,0),"") | AG15: =IF(AD15="", "", IF(ISNUMBER(MATCH(SUBSTITUTE(AD15, "_AM1", ""), 'Resumo Mapa'!A:A, 0)), "✅", "❌"))
A16: 8 | E16: =IFERROR(VLOOKUP(CONCATENATE("Onda 1"," - ",A16),'Dist expedição'!P:S,3,0),"") | F16: =IFERROR(VLOOKUP(E16,'Dist expedição'!$C:$E,2,0),"") | G16: =IFERROR(VLOOKUP(E16,'Dist expedição'!$C:$F,4,0),"") | H16: =IF(E16="", "", IF(ISNUMBER(MATCH(SUBSTITUTE(E16, "_AM1", ""), 'Resumo Mapa'!A:A, 0)), "✅", "❌")) | I16: =IFERROR(VLOOKUP(CONCATENATE("Onda 2"," - ",A16),'Dist expedição'!P:S,3,0),"") | J16: =IFERROR(VLOOKUP(I16,'Dist expedição'!$C:$E,2,0),"") | K16: =IFERROR(VLOOKUP(I16,'Dist expedição'!$C:$F,4,0),"") | L16: =IF(I16="", "", IF(ISNUMBER(MATCH(SUBSTITUTE(I16, "_AM1", ""), 'Resumo Mapa'!A:A, 0)), "✅", "❌")) | M16: 8 | N16: =IFERROR(VLOOKUP(CONCATENATE("Onda 3"," - ",A16),'Dist expedição'!P:S,3,0),"") | O16: =IFERROR(VLOOKUP(N16,'Dist expedição'!$C:$E,2,0),"") | P16: =IFERROR(VLOOKUP(N16,'Dist expedição'!$C:$F,4,0),"") | Q16: =IF(N16="", "", IF(ISNUMBER(MATCH(SUBSTITUTE(N16, "_AM1", ""), 'Resumo Mapa'!A:A, 0)), "✅", "❌")) | R16: =IFERROR(VLOOKUP(CONCATENATE("Onda 4"," - ",A16),'Dist expedição'!P:S,3,0),"") | S16: =IFERROR(VLOOKUP(R16,'Dist expedição'!$C:$E,2,0),"") | T16: =IFERROR(VLOOKUP(R16,'Dist expedição'!$C:$F,4,0),"") | U16: =IF(R16="", "", IF(ISNUMBER(MATCH(SUBSTITUTE(R16, "_AM1", ""), 'Resumo Mapa'!A:A, 0)), "✅", "❌")) | V16: =IFERROR(VLOOKUP(CONCATENATE("Onda 5"," - ",A16),'Dist expedição'!P:S,3,0),"") | W16: =IFERROR(VLOOKUP(V16,'Dist expedição'!$C:$E,2,0),"") | X16: =IFERROR(VLOOKUP(V16,'Dist expedição'!$C:$F,4,0),"") | Y16: =IF(V16="", "", IF(ISNUMBER(MATCH(SUBSTITUTE(V16, "_AM1", ""), 'Resumo Mapa'!A:A, 0)), "✅", "❌")) | Z16: =IFERROR(VLOOKUP(CONCATENATE("Onda 6"," - ",A16),'Dist expedição'!P:S,3,0),"") | AA16: =IFERROR(VLOOKUP(Z16,'Dist expedição'!$C:$E,2,0),"") | AB16: =IFERROR(VLOOKUP(Z16,'Dist expedição'!$C:$F,4,0),"") | AC16: =IF(Z16="", "", IF(ISNUMBER(MATCH(SUBSTITUTE(Z16, "_AM1", ""), 'Resumo Mapa'!A:A, 0)), "✅", "❌")) | AD16: =IFERROR(VLOOKUP(CONCATENATE("Onda 7"," - ",A16),'Dist expedição'!P:S,3,0),"") | AE16: =IFERROR(VLOOKUP(AD16,'Dist expedição'!$C:$E,2,0),"") | AF16: =IFERROR(VLOOKUP(AD16,'Dist expedição'!$C:$F,4,0),"") | AG16: =IF(AD16="", "", IF(ISNUMBER(MATCH(SUBSTITUTE(AD16, "_AM1", ""), 'Resumo Mapa'!A:A, 0)), "✅", "❌"))
A17: 9 | B17: DOUGLAS | C17: ALFREDO (D) | D17: BARBARA | E17: =IFERROR(VLOOKUP(CONCATENATE("Onda 1"," - ",A17),'Dist expedição'!P:S,3,0),"") | F17: =IFERROR(VLOOKUP(E17,'Dist expedição'!$C:$E,2,0),"") | G17: =IFERROR(VLOOKUP(E17,'Dist expedição'!$C:$F,4,0),"") | H17: =IF(E17="", "", IF(ISNUMBER(MATCH(SUBSTITUTE(E17, "_AM1", ""), 'Resumo Mapa'!A:A, 0)), "✅", "❌")) | I17: =IFERROR(VLOOKUP(CONCATENATE("Onda 2"," - ",A17),'Dist expedição'!P:S,3,0),"") | J17: =IFERROR(VLOOKUP(I17,'Dist expedição'!$C:$E,2,0),"") | K17: =IFERROR(VLOOKUP(I17,'Dist expedição'!$C:$F,4,0),"") | L17: =IF(I17="", "", IF(ISNUMBER(MATCH(SUBSTITUTE(I17, "_AM1", ""), 'Resumo Mapa'!A:A, 0)), "✅", "❌")) | M17: 9 | N17: =IFERROR(VLOOKUP(CONCATENATE("Onda 3"," - ",A17),'Dist expedição'!P:S,3,0),"") -> Q11_AM1 | O17: =IFERROR(VLOOKUP(N17,'Dist expedição'!$C:$E,2,0),"") -> AM1_118 | P17: =IFERROR(VLOOKUP(N17,'Dist expedição'!$C:$F,4,0),"") -> PARCEIRO SPOT SOLUCOES | Q17: =IF(N17="", "", IF(ISNUMBER(MATCH(SUBSTITUTE(N17, "_AM1", ""), 'Resumo Mapa'!A:A, 0)), "✅", "❌")) -> ❌ | R17: =IFERROR(VLOOKUP(CONCATENATE("Onda 4"," - ",A17),'Dist expedição'!P:S,3,0),"") -> A7_AM1 | S17: =IFERROR(VLOOKUP(R17,'Dist expedição'!$C:$E,2,0),"") -> AM1_116 | T17: =IFERROR(VLOOKUP(R17,'Dist expedição'!$C:$F,4,0),"") -> PARCEIRO SPOT SOLUCOES | U17: =IF(R17="", "", IF(ISNUMBER(MATCH(SUBSTITUTE(R17, "_AM1", ""), 'Resumo Mapa'!A:A, 0)), "✅", "❌")) -> ❌ | V17: =IFERROR(VLOOKUP(CONCATENATE("Onda 5"," - ",A17),'Dist expedição'!P:S,3,0),"") -> D3_AM1 | W17: =IFERROR(VLOOKUP(V17,'Dist expedição'!$C:$E,2,0),"") -> AM1_51 | X17: =IFERROR(VLOOKUP(V17,'Dist expedição'!$C:$F,4,0),"") -> PARCEIRO SPOT SOLUCOES | Y17: =IF(V17="", "", IF(ISNUMBER(MATCH(SUBSTITUTE(V17, "_AM1", ""), 'Resumo Mapa'!A:A, 0)), "✅", "❌")) -> ❌ | Z17: =IFERROR(VLOOKUP(CONCATENATE("Onda 6"," - ",A17),'Dist expedição'!P:S,3,0),"") -> VN2_AM1 | AA17: =IFERROR(VLOOKUP(Z17,'Dist expedição'!$C:$E,2,0),"") -> AM1_96 | AB17: =IFERROR(VLOOKUP(Z17,'Dist expedição'!$C:$F,4,0),"") -> PARCEIRO SPOT SOLUCOES | AC17: =IF(Z17="", "", IF(ISNUMBER(MATCH(SUBSTITUTE(Z17, "_AM1", ""), 'Resumo Mapa'!A:A, 0)), "✅", "❌")) -> ✅ | AD17: =IFERROR(VLOOKUP(CONCATENATE("Onda 7"," - ",A17),'Dist expedição'!P:S,3,0),"") | AE17: =IFERROR(VLOOKUP(AD17,'Dist expedição'!$C:$E,2,0),"") | AF17: =IFERROR(VLOOKUP(AD17,'Dist expedição'!$C:$F,4,0),"") | AG17: =IF(AD17="", "", IF(ISNUMBER(MATCH(SUBSTITUTE(AD17, "_AM1", ""), 'Resumo Mapa'!A:A, 0)), "✅", "❌"))
A18: 10 | B18: FABIANA (D) | C18: ALFREDO (D) | D18: BARBARA | E18: =IFERROR(VLOOKUP(CONCATENATE("Onda 1"," - ",A18),'Dist expedição'!P:S,3,0),"") | F18: =IFERROR(VLOOKUP(E18,'Dist expedição'!$C:$E,2,0),"") | G18: =IFERROR(VLOOKUP(E18,'Dist expedição'!$C:$F,4,0),"") | H18: =IF(E18="", "", IF(ISNUMBER(MATCH(SUBSTITUTE(E18, "_AM1", ""), 'Resumo Mapa'!A:A, 0)), "✅", "❌")) | I18: =IFERROR(VLOOKUP(CONCATENATE("Onda 2"," - ",A18),'Dist expedição'!P:S,3,0),"") | J18: =IFERROR(VLOOKUP(I18,'Dist expedição'!$C:$E,2,0),"") | K18: =IFERROR(VLOOKUP(I18,'Dist expedição'!$C:$F,4,0),"") | L18: =IF(I18="", "", IF(ISNUMBER(MATCH(SUBSTITUTE(I18, "_AM1", ""), 'Resumo Mapa'!A:A, 0)), "✅", "❌")) | M18: 10 | N18: =IFERROR(VLOOKUP(CONCATENATE("Onda 3"," - ",A18),'Dist expedição'!P:S,3,0),"") -> P11_AM1 | O18: =IFERROR(VLOOKUP(N18,'Dist expedição'!$C:$E,2,0),"") -> AM1_56 | P18: =IFERROR(VLOOKUP(N18,'Dist expedição'!$C:$F,4,0),"") -> RodaCoop | Q18: =IF(N18="", "", IF(ISNUMBER(MATCH(SUBSTITUTE(N18, "_AM1", ""), 'Resumo Mapa'!A:A, 0)), "✅", "❌")) -> ❌ | R18: =IFERROR(VLOOKUP(CONCATENATE("Onda 4"," - ",A18),'Dist expedição'!P:S,3,0),"") -> Q3_AM1 | S18: =IFERROR(VLOOKUP(R18,'Dist expedição'!$C:$E,2,0),"") -> AM1_68 | T18: =IFERROR(VLOOKUP(R18,'Dist expedição'!$C:$F,4,0),"") -> Hawk Transportes | U18: =IF(R18="", "", IF(ISNUMBER(MATCH(SUBSTITUTE(R18, "_AM1", ""), 'Resumo Mapa'!A:A, 0)), "✅", "❌")) -> ❌ | V18: =IFERROR(VLOOKUP(CONCATENATE("Onda 5"," - ",A18),'Dist expedição'!P:S,3,0),"") -> D2_AM1 | W18: =IFERROR(VLOOKUP(V18,'Dist expedição'!$C:$E,2,0),"") -> AM1_47 | X18: =IFERROR(VLOOKUP(V18,'Dist expedição'!$C:$F,4,0),"") -> PARCEIRO SPOT SOLUCOES | Y18: =IF(V18="", "", IF(ISNUMBER(MATCH(SUBSTITUTE(V18, "_AM1", ""), 'Resumo Mapa'!A:A, 0)), "✅", "❌")) -> ❌ | Z18: =IFERROR(VLOOKUP(CONCATENATE("Onda 6"," - ",A18),'Dist expedição'!P:S,3,0),"") -> H1_AM1 | AA18: =IFERROR(VLOOKUP(Z18,'Dist expedição'!$C:$E,2,0),"") -> AM1_21 | AB18: =IFERROR(VLOOKUP(Z18,'Dist expedição'!$C:$F,4,0),"") -> Hawk Transportes | AC18: =IF(Z18="", "", IF(ISNUMBER(MATCH(SUBSTITUTE(Z18, "_AM1", ""), 'Resumo Mapa'!A:A, 0)), "✅", "❌")) -> ❌ | AD18: =IFERROR(VLOOKUP(CONCATENATE("Onda 7"," - ",A18),'Dist expedição'!P:S,3,0),"") | AE18: =IFERROR(VLOOKUP(AD18,'Dist expedição'!$C:$E,2,0),"") | AF18: =IFERROR(VLOOKUP(AD18,'Dist expedição'!$C:$F,4,0),"") | AG18: =IF(AD18="", "", IF(ISNUMBER(MATCH(SUBSTITUTE(AD18, "_AM1", ""), 'Resumo Mapa'!A:A, 0)), "✅", "❌"))
A19: 11 | B19: REGINA | C19: ALEXANDRE (D) | D19: BARBARA | E19: =IFERROR(VLOOKUP(CONCATENATE("Onda 1"," - ",A19),'Dist expedição'!P:S,3,0),"") | F19: =IFERROR(VLOOKUP(E19,'Dist expedição'!$C:$E,2,0),"") | G19: =IFERROR(VLOOKUP(E19,'Dist expedição'!$C:$F,4,0),"") | H19: =IF(E19="", "", IF(ISNUMBER(MATCH(SUBSTITUTE(E19, "_AM1", ""), 'Resumo Mapa'!A:A, 0)), "✅", "❌")) | I19: =IFERROR(VLOOKUP(CONCATENATE("Onda 2"," - ",A19),'Dist expedição'!P:S,3,0),"") | J19: =IFERROR(VLOOKUP(I19,'Dist expedição'!$C:$E,2,0),"") | K19: =IFERROR(VLOOKUP(I19,'Dist expedição'!$C:$F,4,0),"") | L19: =IF(I19="", "", IF(ISNUMBER(MATCH(SUBSTITUTE(I19, "_AM1", ""), 'Resumo Mapa'!A:A, 0)), "✅", "❌")) | M19: 11 | N19: =IFERROR(VLOOKUP(CONCATENATE("Onda 3"," - ",A19),'Dist expedição'!P:S,3,0),"") -> P1_AM1 | O19: =IFERROR(VLOOKUP(N19,'Dist expedição'!$C:$E,2,0),"") -> AM1_71 | P19: =IFERROR(VLOOKUP(N19,'Dist expedição'!$C:$F,4,0),"") -> HELP ME SOLUCOES | Q19: =IF(N19="", "", IF(ISNUMBER(MATCH(SUBSTITUTE(N19, "_AM1", ""), 'Resumo Mapa'!A:A, 0)), "✅", "❌")) -> ❌ | R19: =IFERROR(VLOOKUP(CONCATENATE("Onda 4"," - ",A19),'Dist expedição'!P:S,3,0),"") -> H11_AM1 | S19: =IFERROR(VLOOKUP(R19,'Dist expedição'!$C:$E,2,0),"") -> AM1_22 | T19: =IFERROR(VLOOKUP(R19,'Dist expedição'!$C:$F,4,0),"") -> Hawk Transportes | U19: =IF(R19="", "", IF(ISNUMBER(MATCH(SUBSTITUTE(R19, "_AM1", ""), 'Resumo Mapa'!A:A, 0)), "✅", "❌")) -> ❌ | V19: =IFERROR(VLOOKUP(CONCATENATE("Onda 5"," - ",A19),'Dist expedição'!P:S,3,0),"") -> C4_AM1 | W19: =IFERROR(VLOOKUP(V19,'Dist expedição'!$C:$E,2,0),"") -> AM1_98 | X19: =IFERROR(VLOOKUP(V19,'Dist expedição'!$C:$F,4,0),"") -> PARCEIRO SPOT SOLUCOES | Y19: =IF(V19="", "", IF(ISNUMBER(MATCH(SUBSTITUTE(V19, "_AM1", ""), 'Resumo Mapa'!A:A, 0)), "✅", "❌")) -> ❌ | Z19: =IFERROR(VLOOKUP(CONCATENATE("Onda 6"," - ",A19),'Dist expedição'!P:S,3,0),"") -> H6_AM1 | AA19: =IFERROR(VLOOKUP(Z19,'Dist expedição'!$C:$E,2,0),"") -> AM1_48 | AB19: =IFERROR(VLOOKUP(Z19,'Dist expedição'!$C:$F,4,0),"") -> Hawk Transportes | AC19: =IF(Z19="", "", IF(ISNUMBER(MATCH(SUBSTITUTE(Z19, "_AM1", ""), 'Resumo Mapa'!A:A, 0)), "✅", "❌")) -> ❌ | AD19: =IFERROR(VLOOKUP(CONCATENATE("Onda 7"," - ",A19),'Dist expedição'!P:S,3,0),"") | AE19: =IFERROR(VLOOKUP(AD19,'Dist expedição'!$C:$E,2,0),"") | AF19: =IFERROR(VLOOKUP(AD19,'Dist expedição'!$C:$F,4,0),"") | AG19: =IF(AD19="", "", IF(ISNUMBER(MATCH(SUBSTITUTE(AD19, "_AM1", ""), 'Resumo Mapa'!A:A, 0)), "✅", "❌"))
A20: 12 | B20: LARISSA | C20: ALEXANDRE (D) | D20: BARBARA | E20: =IFERROR(VLOOKUP(CONCATENATE("Onda 1"," - ",A20),'Dist expedição'!P:S,3,0),"") | F20: =IFERROR(VLOOKUP(E20,'Dist expedição'!$C:$E,2,0),"") | G20: =IFERROR(VLOOKUP(E20,'Dist expedição'!$C:$F,4,0),"") | H20: =IF(E20="", "", IF(ISNUMBER(MATCH(SUBSTITUTE(E20, "_AM1", ""), 'Resumo Mapa'!A:A, 0)), "✅", "❌")) | I20: =IFERROR(VLOOKUP(CONCATENATE("Onda 2"," - ",A20),'Dist expedição'!P:S,3,0),"") | J20: =IFERROR(VLOOKUP(I20,'Dist expedição'!$C:$E,2,0),"") | K20: =IFERROR(VLOOKUP(I20,'Dist expedição'!$C:$F,4,0),"") | L20: =IF(I20="", "", IF(ISNUMBER(MATCH(SUBSTITUTE(I20, "_AM1", ""), 'Resumo Mapa'!A:A, 0)), "✅", "❌")) | M20: 12 | N20: =IFERROR(VLOOKUP(CONCATENATE("Onda 3"," - ",A20),'Dist expedição'!P:S,3,0),"") -> Q2_AM1 | O20: =IFERROR(VLOOKUP(N20,'Dist expedição'!$C:$E,2,0),"") -> AM1_16 | P20: =IFERROR(VLOOKUP(N20,'Dist expedição'!$C:$F,4,0),"") -> Hawk Transportes | Q20: =IF(N20="", "", IF(ISNUMBER(MATCH(SUBSTITUTE(N20, "_AM1", ""), 'Resumo Mapa'!A:A, 0)), "✅", "❌")) -> ❌ | R20: =IFERROR(VLOOKUP(CONCATENATE("Onda 4"," - ",A20),'Dist expedição'!P:S,3,0),"") -> I8_AM1 | S20: =IFERROR(VLOOKUP(R20,'Dist expedição'!$C:$E,2,0),"") -> AM1_57 | T20: =IFERROR(VLOOKUP(R20,'Dist expedição'!$C:$F,4,0),"") -> Hawk Transportes | U20: =IF(R20="", "", IF(ISNUMBER(MATCH(SUBSTITUTE(R20, "_AM1", ""), 'Resumo Mapa'!A:A, 0)), "✅", "❌")) -> ❌ | V20: =IFERROR(VLOOKUP(CONCATENATE("Onda 5"," - ",A20),'Dist expedição'!P:S,3,0),"") -> VN3_AM1 | W20: =IFERROR(VLOOKUP(V20,'Dist expedição'!$C:$E,2,0),"") -> AM1_50 | X20: =IFERROR(VLOOKUP(V20,'Dist expedição'!$C:$F,4,0),"") -> PARCEIRO SPOT SOLUCOES | Y20: =IF(V20="", "", IF(ISNUMBER(MATCH(SUBSTITUTE(V20, "_AM1", ""), 'Resumo Mapa'!A:A, 0)), "✅", "❌")) -> ✅ | Z20: =IFERROR(VLOOKUP(CONCATENATE("Onda 6"," - ",A20),'Dist expedição'!P:S,3,0),"") -> G1_AM1 | AA20: =IFERROR(VLOOKUP(Z20,'Dist expedição'!$C:$E,2,0),"") -> AM1_1 | AB20: =IFERROR(VLOOKUP(Z20,'Dist expedição'!$C:$F,4,0),"") -> Hawk Transportes | AC20: =IF(Z20="", "", IF(ISNUMBER(MATCH(SUBSTITUTE(Z20, "_AM1", ""), 'Resumo Mapa'!A:A, 0)), "✅", "❌")) -> ❌ | AD20: =IFERROR(VLOOKUP(CONCATENATE("Onda 7"," - ",A20),'Dist expedição'!P:S,3,0),"") | AE20: =IFERROR(VLOOKUP(AD20,'Dist expedição'!$C:$E,2,0),"") | AF20: =IFERROR(VLOOKUP(AD20,'Dist expedição'!$C:$F,4,0),"") | AG20: =IF(AD20="", "", IF(ISNUMBER(MATCH(SUBSTITUTE(AD20, "_AM1", ""), 'Resumo Mapa'!A:A, 0)), "✅", "❌"))
A21: 13 | B21: LUCIANA | C21: ANTONIO PEDRO (D) | D21: BARBARA | E21: =IFERROR(VLOOKUP(CONCATENATE("Onda 1"," - ",A21),'Dist expedição'!P:S,3,0),"") | F21: =IFERROR(VLOOKUP(E21,'Dist expedição'!$C:$E,2,0),"") | G21: =IFERROR(VLOOKUP(E21,'Dist expedição'!$C:$F,4,0),"") | H21: =IF(E21="", "", IF(ISNUMBER(MATCH(SUBSTITUTE(E21, "_AM1", ""), 'Resumo Mapa'!A:A, 0)), "✅", "❌")) | I21: =IFERROR(VLOOKUP(CONCATENATE("Onda 2"," - ",A21),'Dist expedição'!P:S,3,0),"") | J21: =IFERROR(VLOOKUP(I21,'Dist expedição'!$C:$E,2,0),"") | K21: =IFERROR(VLOOKUP(I21,'Dist expedição'!$C:$F,4,0),"") | L21: =IF(I21="", "", IF(ISNUMBER(MATCH(SUBSTITUTE(I21, "_AM1", ""), 'Resumo Mapa'!A:A, 0)), "✅", "❌")) | M21: 13 | N21: =IFERROR(VLOOKUP(CONCATENATE("Onda 3"," - ",A21),'Dist expedição'!P:S,3,0),"") -> P10_AM1 | O21: =IFERROR(VLOOKUP(N21,'Dist expedição'!$C:$E,2,0),"") -> AM1_66 | P21: =IFERROR(VLOOKUP(N21,'Dist expedição'!$C:$F,4,0),"") -> Hawk Transportes | Q21: =IF(N21="", "", IF(ISNUMBER(MATCH(SUBSTITUTE(N21, "_AM1", ""), 'Resumo Mapa'!A:A, 0)), "✅", "❌")) -> ❌ | R21: =IFERROR(VLOOKUP(CONCATENATE("Onda 4"," - ",A21),'Dist expedição'!P:S,3,0),"") -> A8_AM1 | S21: =IFERROR(VLOOKUP(R21,'Dist expedição'!$C:$E,2,0),"") -> AM1_120 | T21: =IFERROR(VLOOKUP(R21,'Dist expedição'!$C:$F,4,0),"") -> Hawk Transportes | U21: =IF(R21="", "", IF(ISNUMBER(MATCH(SUBSTITUTE(R21, "_AM1", ""), 'Resumo Mapa'!A:A, 0)), "✅", "❌")) -> ❌ | V21: =IFERROR(VLOOKUP(CONCATENATE("Onda 5"," - ",A21),'Dist expedição'!P:S,3,0),"") -> B9_AM1 | W21: =IFERROR(VLOOKUP(V21,'Dist expedição'!$C:$E,2,0),"") -> AM1_99 | X21: =IFERROR(VLOOKUP(V21,'Dist expedição'!$C:$F,4,0),"") -> HELP ME SOLUCOES | Y21: =IF(V21="", "", IF(ISNUMBER(MATCH(SUBSTITUTE(V21, "_AM1", ""), 'Resumo Mapa'!A:A, 0)), "✅", "❌")) -> ❌ | Z21: =IFERROR(VLOOKUP(CONCATENATE("Onda 6"," - ",A21),'Dist expedição'!P:S,3,0),"") -> H9_AM1 | AA21: =IFERROR(VLOOKUP(Z21,'Dist expedição'!$C:$E,2,0),"") -> AM1_54 | AB21: =IFERROR(VLOOKUP(Z21,'Dist expedição'!$C:$F,4,0),"") -> Hawk Transportes | AC21: =IF(Z21="", "", IF(ISNUMBER(MATCH(SUBSTITUTE(Z21, "_AM1", ""), 'Resumo Mapa'!A:A, 0)), "✅", "❌")) -> ❌ | AD21: =IFERROR(VLOOKUP(CONCATENATE("Onda 7"," - ",A21),'Dist expedição'!P:S,3,0),"") | AE21: =IFERROR(VLOOKUP(AD21,'Dist expedição'!$C:$E,2,0),"") | AF21: =IFERROR(VLOOKUP(AD21,'Dist expedição'!$C:$F,4,0),"") | AG21: =IF(AD21="", "", IF(ISNUMBER(MATCH(SUBSTITUTE(AD21, "_AM1", ""), 'Resumo Mapa'!A:A, 0)), "✅", "❌"))
A22: 14 | B22: CAMYLLA | C22: ANTONIO PEDRO (D) | D22: BARBARA | E22: =IFERROR(VLOOKUP(CONCATENATE("Onda 1"," - ",A22),'Dist expedição'!P:S,3,0),"") | F22: =IFERROR(VLOOKUP(E22,'Dist expedição'!$C:$E,2,0),"") | G22: =IFERROR(VLOOKUP(E22,'Dist expedição'!$C:$F,4,0),"") | H22: =IF(E22="", "", IF(ISNUMBER(MATCH(SUBSTITUTE(E22, "_AM1", ""), 'Resumo Mapa'!A:A, 0)), "✅", "❌")) | I22: =IFERROR(VLOOKUP(CONCATENATE("Onda 2"," - ",A22),'Dist expedição'!P:S,3,0),"") | J22: =IFERROR(VLOOKUP(I22,'Dist expedição'!$C:$E,2,0),"") | K22: =IFERROR(VLOOKUP(I22,'Dist expedição'!$C:$F,4,0),"") | L22: =IF(I22="", "", IF(ISNUMBER(MATCH(SUBSTITUTE(I22, "_AM1", ""), 'Resumo Mapa'!A:A, 0)), "✅", "❌")) | M22: 14 | N22: =IFERROR(VLOOKUP(CONCATENATE("Onda 3"," - ",A22),'Dist expedição'!P:S,3,0),"") -> P12_AM1 | O22: =IFERROR(VLOOKUP(N22,'Dist expedição'!$C:$E,2,0),"") -> AM1_42 | P22: =IFERROR(VLOOKUP(N22,'Dist expedição'!$C:$F,4,0),"") -> Hawk Transportes | Q22: =IF(N22="", "", IF(ISNUMBER(MATCH(SUBSTITUTE(N22, "_AM1", ""), 'Resumo Mapa'!A:A, 0)), "✅", "❌")) -> ❌ | R22: =IFERROR(VLOOKUP(CONCATENATE("Onda 4"," - ",A22),'Dist expedição'!P:S,3,0),"") -> B3_AM1 | S22: =IFERROR(VLOOKUP(R22,'Dist expedição'!$C:$E,2,0),"") -> AM1_111 | T22: =IFERROR(VLOOKUP(R22,'Dist expedição'!$C:$F,4,0),"") -> Hawk Transportes | U22: =IF(R22="", "", IF(ISNUMBER(MATCH(SUBSTITUTE(R22, "_AM1", ""), 'Resumo Mapa'!A:A, 0)), "✅", "❌")) -> ❌ | V22: =IFERROR(VLOOKUP(CONCATENATE("Onda 5"," - ",A22),'Dist expedição'!P:S,3,0),"") -> B6_AM1 | W22: =IFERROR(VLOOKUP(V22,'Dist expedição'!$C:$E,2,0),"") -> AM1_100 | X22: =IFERROR(VLOOKUP(V22,'Dist expedição'!$C:$F,4,0),"") -> HELP ME SOLUCOES | Y22: =IF(V22="", "", IF(ISNUMBER(MATCH(SUBSTITUTE(V22, "_AM1", ""), 'Resumo Mapa'!A:A, 0)), "✅", "❌")) -> ❌ | Z22: =IFERROR(VLOOKUP(CONCATENATE("Onda 6"," - ",A22),'Dist expedição'!P:S,3,0),"") -> H12_AM1 | AA22: =IFERROR(VLOOKUP(Z22,'Dist expedição'!$C:$E,2,0),"") -> AM1_55 | AB22: =IFERROR(VLOOKUP(Z22,'Dist expedição'!$C:$F,4,0),"") -> Hawk Transportes | AC22: =IF(Z22="", "", IF(ISNUMBER(MATCH(SUBSTITUTE(Z22, "_AM1", ""), 'Resumo Mapa'!A:A, 0)), "✅", "❌")) -> ❌ | AD22: =IFERROR(VLOOKUP(CONCATENATE("Onda 7"," - ",A22),'Dist expedição'!P:S,3,0),"") | AE22: =IFERROR(VLOOKUP(AD22,'Dist expedição'!$C:$E,2,0),"") | AF22: =IFERROR(VLOOKUP(AD22,'Dist expedição'!$C:$F,4,0),"") | AG22: =IF(AD22="", "", IF(ISNUMBER(MATCH(SUBSTITUTE(AD22, "_AM1", ""), 'Resumo Mapa'!A:A, 0)), "✅", "❌"))
A23: 15 | B23: ROGER | C23: BRENO (D) | D23: BARBARA | E23: =IFERROR(VLOOKUP(CONCATENATE("Onda 1"," - ",A23),'Dist expedição'!P:S,3,0),"") | F23: =IFERROR(VLOOKUP(E23,'Dist expedição'!$C:$E,2,0),"") | G23: =IFERROR(VLOOKUP(E23,'Dist expedição'!$C:$F,4,0),"") | H23: =IF(E23="", "", IF(ISNUMBER(MATCH(SUBSTITUTE(E23, "_AM1", ""), 'Resumo Mapa'!A:A, 0)), "✅", "❌")) | I23: =IFERROR(VLOOKUP(CONCATENATE("Onda 2"," - ",A23),'Dist expedição'!P:S,3,0),"") | J23: =IFERROR(VLOOKUP(I23,'Dist expedição'!$C:$E,2,0),"") | K23: =IFERROR(VLOOKUP(I23,'Dist expedição'!$C:$F,4,0),"") | L23: =IF(I23="", "", IF(ISNUMBER(MATCH(SUBSTITUTE(I23, "_AM1", ""), 'Resumo Mapa'!A:A, 0)), "✅", "❌")) | M23: 15 | N23: =IFERROR(VLOOKUP(CONCATENATE("Onda 3"," - ",A23),'Dist expedição'!P:S,3,0),"") -> Q1_AM1 | O23: =IFERROR(VLOOKUP(N23,'Dist expedição'!$C:$E,2,0),"") -> AM1_4 | P23: =IFERROR(VLOOKUP(N23,'Dist expedição'!$C:$F,4,0),"") -> FLASHLOG | Q23: =IF(N23="", "", IF(ISNUMBER(MATCH(SUBSTITUTE(N23, "_AM1", ""), 'Resumo Mapa'!A:A, 0)), "✅", "❌")) -> ❌ | R23: =IFERROR(VLOOKUP(CONCATENATE("Onda 4"," - ",A23),'Dist expedição'!P:S,3,0),"") -> B1_AM1 | S23: =IFERROR(VLOOKUP(R23,'Dist expedição'!$C:$E,2,0),"") -> AM1_115 | T23: =IFERROR(VLOOKUP(R23,'Dist expedição'!$C:$F,4,0),"") -> PARCEIRO SPOT SOLUCOES | U23: =IF(R23="", "", IF(ISNUMBER(MATCH(SUBSTITUTE(R23, "_AM1", ""), 'Resumo Mapa'!A:A, 0)), "✅", "❌")) -> ❌ | V23: =IFERROR(VLOOKUP(CONCATENATE("Onda 5"," - ",A23),'Dist expedição'!P:S,3,0),"") -> F1_AM1 | W23: =IFERROR(VLOOKUP(V23,'Dist expedição'!$C:$E,2,0),"") -> AM1_2 | X23: =IFERROR(VLOOKUP(V23,'Dist expedição'!$C:$F,4,0),"") -> PARCEIRO SPOT SOLUCOES | Y23: =IF(V23="", "", IF(ISNUMBER(MATCH(SUBSTITUTE(V23, "_AM1", ""), 'Resumo Mapa'!A:A, 0)), "✅", "❌")) -> ❌ | Z23: =IFERROR(VLOOKUP(CONCATENATE("Onda 6"," - ",A23),'Dist expedição'!P:S,3,0),"") -> VN4_AM1 | AA23: =IFERROR(VLOOKUP(Z23,'Dist expedição'!$C:$E,2,0),"") -> AM1_108 | AB23: =IFERROR(VLOOKUP(Z23,'Dist expedição'!$C:$F,4,0),"") -> PARCEIRO SPOT SOLUCOES | AC23: =IF(Z23="", "", IF(ISNUMBER(MATCH(SUBSTITUTE(Z23, "_AM1", ""), 'Resumo Mapa'!A:A, 0)), "✅", "❌")) -> ✅ | AD23: =IFERROR(VLOOKUP(CONCATENATE("Onda 7"," - ",A23),'Dist expedição'!P:S,3,0),"") | AE23: =IFERROR(VLOOKUP(AD23,'Dist expedição'!$C:$E,2,0),"") | AF23: =IFERROR(VLOOKUP(AD23,'Dist expedição'!$C:$F,4,0),"") | AG23: =IF(AD23="", "", IF(ISNUMBER(MATCH(SUBSTITUTE(AD23, "_AM1", ""), 'Resumo Mapa'!A:A, 0)), "✅", "❌"))
A24: 16 | B24: HEBERT | C24: BRENO (D) | D24: LEIA | E24: =IFERROR(VLOOKUP(CONCATENATE("Onda 1"," - ",A24),'Dist expedição'!P:S,3,0),"") | F24: =IFERROR(VLOOKUP(E24,'Dist expedição'!$C:$E,2,0),"") | G24: =IFERROR(VLOOKUP(E24,'Dist expedição'!$C:$F,4,0),"") | H24: =IF(E24="", "", IF(ISNUMBER(MATCH(SUBSTITUTE(E24, "_AM1", ""), 'Resumo Mapa'!A:A, 0)), "✅", "❌")) | I24: =IFERROR(VLOOKUP(CONCATENATE("Onda 2"," - ",A24),'Dist expedição'!P:S,3,0),"") | J24: =IFERROR(VLOOKUP(I24,'Dist expedição'!$C:$E,2,0),"") | K24: =IFERROR(VLOOKUP(I24,'Dist expedição'!$C:$F,4,0),"") | L24: =IF(I24="", "", IF(ISNUMBER(MATCH(SUBSTITUTE(I24, "_AM1", ""), 'Resumo Mapa'!A:A, 0)), "✅", "❌")) | M24: 16 | N24: =IFERROR(VLOOKUP(CONCATENATE("Onda 3"," - ",A24),'Dist expedição'!P:S,3,0),"") -> Q10_AM1 | O24: =IFERROR(VLOOKUP(N24,'Dist expedição'!$C:$E,2,0),"") -> AM1_8 | P24: =IFERROR(VLOOKUP(N24,'Dist expedição'!$C:$F,4,0),"") -> FLASHLOG | Q24: =IF(N24="", "", IF(ISNUMBER(MATCH(SUBSTITUTE(N24, "_AM1", ""), 'Resumo Mapa'!A:A, 0)), "✅", "❌")) -> ❌ | R24: =IFERROR(VLOOKUP(CONCATENATE("Onda 4"," - ",A24),'Dist expedição'!P:S,3,0),"") -> Q7_AM1 | S24: =IFERROR(VLOOKUP(R24,'Dist expedição'!$C:$E,2,0),"") -> AM1_59 | T24: =IFERROR(VLOOKUP(R24,'Dist expedição'!$C:$F,4,0),"") -> PARCEIRO SPOT SOLUCOES | U24: =IF(R24="", "", IF(ISNUMBER(MATCH(SUBSTITUTE(R24, "_AM1", ""), 'Resumo Mapa'!A:A, 0)), "✅", "❌")) -> ❌ | V24: =IFERROR(VLOOKUP(CONCATENATE("Onda 5"," - ",A24),'Dist expedição'!P:S,3,0),"") -> B8_AM1 | W24: =IFERROR(VLOOKUP(V24,'Dist expedição'!$C:$E,2,0),"") -> AM1_95 | X24: =IFERROR(VLOOKUP(V24,'Dist expedição'!$C:$F,4,0),"") -> PARCEIRO SPOT SOLUCOES | Y24: =IF(V24="", "", IF(ISNUMBER(MATCH(SUBSTITUTE(V24, "_AM1", ""), 'Resumo Mapa'!A:A, 0)), "✅", "❌")) -> ❌ | Z24: =IFERROR(VLOOKUP(CONCATENATE("Onda 6"," - ",A24),'Dist expedição'!P:S,3,0),"") -> H10_AM1 | AA24: =IFERROR(VLOOKUP(Z24,'Dist expedição'!$C:$E,2,0),"") -> AM1_53 | AB24: =IFERROR(VLOOKUP(Z24,'Dist expedição'!$C:$F,4,0),"") -> A L C TRANSPORTES | AC24: =IF(Z24="", "", IF(ISNUMBER(MATCH(SUBSTITUTE(Z24, "_AM1", ""), 'Resumo Mapa'!A:A, 0)), "✅", "❌")) -> ❌ | AD24: =IFERROR(VLOOKUP(CONCATENATE("Onda 7"," - ",A24),'Dist expedição'!P:S,3,0),"") | AE24: =IFERROR(VLOOKUP(AD24,'Dist expedição'!$C:$E,2,0),"") | AF24: =IFERROR(VLOOKUP(AD24,'Dist expedição'!$C:$F,4,0),"") | AG24: =IF(AD24="", "", IF(ISNUMBER(MATCH(SUBSTITUTE(AD24, "_AM1", ""), 'Resumo Mapa'!A:A, 0)), "✅", "❌"))
